{
 "cells": [
  {
   "cell_type": "code",
   "execution_count": 1,
   "metadata": {},
   "outputs": [],
   "source": [
    "from dnn import *\n",
    "from perceptron import *"
   ]
  },
  {
   "cell_type": "code",
   "execution_count": 2,
   "metadata": {},
   "outputs": [],
   "source": [
    "df_train = pd.read_csv('../../Feature_Encoding/data/train_helmert_encoding.csv')\n",
    "df_test = pd.read_csv('../../Feature_Encoding/data/test_helmert_encoding.csv')\n",
    "train = pd.read_csv('../../Feature_Engineering/data/other-cleaned_train.csv')"
   ]
  },
  {
   "cell_type": "code",
   "execution_count": 3,
   "metadata": {},
   "outputs": [],
   "source": [
    "for column in df_test.columns.tolist():\n",
    "    df_test[column] = df_test[column].fillna(0)  \n",
    "\n",
    "df_test= df_test.replace('', 0)"
   ]
  },
  {
   "cell_type": "code",
   "execution_count": 4,
   "metadata": {},
   "outputs": [],
   "source": [
    "y = train.Target\n",
    "x_train, x_validation, y_train, y_validation = model_selection.train_test_split(df_train, y, test_size=0.3, stratify=y)"
   ]
  },
  {
   "cell_type": "code",
   "execution_count": null,
   "metadata": {},
   "outputs": [
    {
     "name": "stderr",
     "output_type": "stream",
     "text": [
      "/home/violeta/.local/lib/python3.8/site-packages/sklearn/model_selection/_validation.py:610: FitFailedWarning: Estimator fit failed. The score on this train-test partition for these parameters will be set to nan. Details: \n",
      "Traceback (most recent call last):\n",
      "  File \"/home/violeta/.local/lib/python3.8/site-packages/sklearn/model_selection/_validation.py\", line 593, in _fit_and_score\n",
      "    estimator.fit(X_train, y_train, **fit_params)\n",
      "  File \"/home/violeta/.local/lib/python3.8/site-packages/tensorflow/python/keras/wrappers/scikit_learn.py\", line 223, in fit\n",
      "    return super(KerasClassifier, self).fit(x, y, **kwargs)\n",
      "  File \"/home/violeta/.local/lib/python3.8/site-packages/tensorflow/python/keras/wrappers/scikit_learn.py\", line 166, in fit\n",
      "    history = self.model.fit(x, y, **fit_args)\n",
      "  File \"/home/violeta/.local/lib/python3.8/site-packages/tensorflow/python/keras/engine/training.py\", line 1100, in fit\n",
      "    tmp_logs = self.train_function(iterator)\n",
      "  File \"/home/violeta/.local/lib/python3.8/site-packages/tensorflow/python/eager/def_function.py\", line 828, in __call__\n",
      "    result = self._call(*args, **kwds)\n",
      "  File \"/home/violeta/.local/lib/python3.8/site-packages/tensorflow/python/eager/def_function.py\", line 871, in _call\n",
      "    self._initialize(args, kwds, add_initializers_to=initializers)\n",
      "  File \"/home/violeta/.local/lib/python3.8/site-packages/tensorflow/python/eager/def_function.py\", line 725, in _initialize\n",
      "    self._stateful_fn._get_concrete_function_internal_garbage_collected(  # pylint: disable=protected-access\n",
      "  File \"/home/violeta/.local/lib/python3.8/site-packages/tensorflow/python/eager/function.py\", line 2969, in _get_concrete_function_internal_garbage_collected\n",
      "    graph_function, _ = self._maybe_define_function(args, kwargs)\n",
      "  File \"/home/violeta/.local/lib/python3.8/site-packages/tensorflow/python/eager/function.py\", line 3361, in _maybe_define_function\n",
      "    graph_function = self._create_graph_function(args, kwargs)\n",
      "  File \"/home/violeta/.local/lib/python3.8/site-packages/tensorflow/python/eager/function.py\", line 3196, in _create_graph_function\n",
      "    func_graph_module.func_graph_from_py_func(\n",
      "  File \"/home/violeta/.local/lib/python3.8/site-packages/tensorflow/python/framework/func_graph.py\", line 990, in func_graph_from_py_func\n",
      "    func_outputs = python_func(*func_args, **func_kwargs)\n",
      "  File \"/home/violeta/.local/lib/python3.8/site-packages/tensorflow/python/eager/def_function.py\", line 634, in wrapped_fn\n",
      "    out = weak_wrapped_fn().__wrapped__(*args, **kwds)\n",
      "  File \"/home/violeta/.local/lib/python3.8/site-packages/tensorflow/python/framework/func_graph.py\", line 977, in wrapper\n",
      "    raise e.ag_error_metadata.to_exception(e)\n",
      "ValueError: in user code:\n",
      "\n",
      "    /home/violeta/.local/lib/python3.8/site-packages/tensorflow/python/keras/engine/training.py:805 train_function  *\n",
      "        return step_function(self, iterator)\n",
      "    /home/violeta/.local/lib/python3.8/site-packages/tensorflow/python/keras/engine/training.py:795 step_function  **\n",
      "        outputs = model.distribute_strategy.run(run_step, args=(data,))\n",
      "    /home/violeta/.local/lib/python3.8/site-packages/tensorflow/python/distribute/distribute_lib.py:1259 run\n",
      "        return self._extended.call_for_each_replica(fn, args=args, kwargs=kwargs)\n",
      "    /home/violeta/.local/lib/python3.8/site-packages/tensorflow/python/distribute/distribute_lib.py:2730 call_for_each_replica\n",
      "        return self._call_for_each_replica(fn, args, kwargs)\n",
      "    /home/violeta/.local/lib/python3.8/site-packages/tensorflow/python/distribute/distribute_lib.py:3417 _call_for_each_replica\n",
      "        return fn(*args, **kwargs)\n",
      "    /home/violeta/.local/lib/python3.8/site-packages/tensorflow/python/keras/engine/training.py:788 run_step  **\n",
      "        outputs = model.train_step(data)\n",
      "    /home/violeta/.local/lib/python3.8/site-packages/tensorflow/python/keras/engine/training.py:754 train_step\n",
      "        y_pred = self(x, training=True)\n",
      "    /home/violeta/.local/lib/python3.8/site-packages/tensorflow/python/keras/engine/base_layer.py:998 __call__\n",
      "        input_spec.assert_input_compatibility(self.input_spec, inputs, self.name)\n",
      "    /home/violeta/.local/lib/python3.8/site-packages/tensorflow/python/keras/engine/input_spec.py:255 assert_input_compatibility\n",
      "        raise ValueError(\n",
      "\n",
      "    ValueError: Input 0 of layer sequential is incompatible with the layer: expected axis -1 of input shape to have value 55 but received input with shape (None, 4281)\n",
      "\n",
      "\n",
      "  warnings.warn(\"Estimator fit failed. The score on this train-test\"\n",
      "/home/violeta/.local/lib/python3.8/site-packages/sklearn/model_selection/_validation.py:610: FitFailedWarning: Estimator fit failed. The score on this train-test partition for these parameters will be set to nan. Details: \n",
      "Traceback (most recent call last):\n",
      "  File \"/home/violeta/.local/lib/python3.8/site-packages/sklearn/model_selection/_validation.py\", line 593, in _fit_and_score\n",
      "    estimator.fit(X_train, y_train, **fit_params)\n",
      "  File \"/home/violeta/.local/lib/python3.8/site-packages/tensorflow/python/keras/wrappers/scikit_learn.py\", line 223, in fit\n",
      "    return super(KerasClassifier, self).fit(x, y, **kwargs)\n",
      "  File \"/home/violeta/.local/lib/python3.8/site-packages/tensorflow/python/keras/wrappers/scikit_learn.py\", line 166, in fit\n",
      "    history = self.model.fit(x, y, **fit_args)\n",
      "  File \"/home/violeta/.local/lib/python3.8/site-packages/tensorflow/python/keras/engine/training.py\", line 1100, in fit\n",
      "    tmp_logs = self.train_function(iterator)\n",
      "  File \"/home/violeta/.local/lib/python3.8/site-packages/tensorflow/python/eager/def_function.py\", line 828, in __call__\n",
      "    result = self._call(*args, **kwds)\n",
      "  File \"/home/violeta/.local/lib/python3.8/site-packages/tensorflow/python/eager/def_function.py\", line 871, in _call\n",
      "    self._initialize(args, kwds, add_initializers_to=initializers)\n",
      "  File \"/home/violeta/.local/lib/python3.8/site-packages/tensorflow/python/eager/def_function.py\", line 725, in _initialize\n",
      "    self._stateful_fn._get_concrete_function_internal_garbage_collected(  # pylint: disable=protected-access\n",
      "  File \"/home/violeta/.local/lib/python3.8/site-packages/tensorflow/python/eager/function.py\", line 2969, in _get_concrete_function_internal_garbage_collected\n",
      "    graph_function, _ = self._maybe_define_function(args, kwargs)\n",
      "  File \"/home/violeta/.local/lib/python3.8/site-packages/tensorflow/python/eager/function.py\", line 3361, in _maybe_define_function\n",
      "    graph_function = self._create_graph_function(args, kwargs)\n",
      "  File \"/home/violeta/.local/lib/python3.8/site-packages/tensorflow/python/eager/function.py\", line 3196, in _create_graph_function\n",
      "    func_graph_module.func_graph_from_py_func(\n",
      "  File \"/home/violeta/.local/lib/python3.8/site-packages/tensorflow/python/framework/func_graph.py\", line 990, in func_graph_from_py_func\n",
      "    func_outputs = python_func(*func_args, **func_kwargs)\n",
      "  File \"/home/violeta/.local/lib/python3.8/site-packages/tensorflow/python/eager/def_function.py\", line 634, in wrapped_fn\n",
      "    out = weak_wrapped_fn().__wrapped__(*args, **kwds)\n",
      "  File \"/home/violeta/.local/lib/python3.8/site-packages/tensorflow/python/framework/func_graph.py\", line 977, in wrapper\n",
      "    raise e.ag_error_metadata.to_exception(e)\n",
      "ValueError: in user code:\n",
      "\n",
      "    /home/violeta/.local/lib/python3.8/site-packages/tensorflow/python/keras/engine/training.py:805 train_function  *\n",
      "        return step_function(self, iterator)\n",
      "    /home/violeta/.local/lib/python3.8/site-packages/tensorflow/python/keras/engine/training.py:795 step_function  **\n",
      "        outputs = model.distribute_strategy.run(run_step, args=(data,))\n",
      "    /home/violeta/.local/lib/python3.8/site-packages/tensorflow/python/distribute/distribute_lib.py:1259 run\n",
      "        return self._extended.call_for_each_replica(fn, args=args, kwargs=kwargs)\n",
      "    /home/violeta/.local/lib/python3.8/site-packages/tensorflow/python/distribute/distribute_lib.py:2730 call_for_each_replica\n",
      "        return self._call_for_each_replica(fn, args, kwargs)\n",
      "    /home/violeta/.local/lib/python3.8/site-packages/tensorflow/python/distribute/distribute_lib.py:3417 _call_for_each_replica\n",
      "        return fn(*args, **kwargs)\n",
      "    /home/violeta/.local/lib/python3.8/site-packages/tensorflow/python/keras/engine/training.py:788 run_step  **\n",
      "        outputs = model.train_step(data)\n",
      "    /home/violeta/.local/lib/python3.8/site-packages/tensorflow/python/keras/engine/training.py:754 train_step\n",
      "        y_pred = self(x, training=True)\n",
      "    /home/violeta/.local/lib/python3.8/site-packages/tensorflow/python/keras/engine/base_layer.py:998 __call__\n",
      "        input_spec.assert_input_compatibility(self.input_spec, inputs, self.name)\n",
      "    /home/violeta/.local/lib/python3.8/site-packages/tensorflow/python/keras/engine/input_spec.py:255 assert_input_compatibility\n",
      "        raise ValueError(\n",
      "\n",
      "    ValueError: Input 0 of layer sequential_1 is incompatible with the layer: expected axis -1 of input shape to have value 55 but received input with shape (None, 4281)\n",
      "\n",
      "\n",
      "  warnings.warn(\"Estimator fit failed. The score on this train-test\"\n"
     ]
    },
    {
     "name": "stderr",
     "output_type": "stream",
     "text": [
      "/home/violeta/.local/lib/python3.8/site-packages/sklearn/model_selection/_validation.py:610: FitFailedWarning: Estimator fit failed. The score on this train-test partition for these parameters will be set to nan. Details: \n",
      "Traceback (most recent call last):\n",
      "  File \"/home/violeta/.local/lib/python3.8/site-packages/sklearn/model_selection/_validation.py\", line 593, in _fit_and_score\n",
      "    estimator.fit(X_train, y_train, **fit_params)\n",
      "  File \"/home/violeta/.local/lib/python3.8/site-packages/tensorflow/python/keras/wrappers/scikit_learn.py\", line 223, in fit\n",
      "    return super(KerasClassifier, self).fit(x, y, **kwargs)\n",
      "  File \"/home/violeta/.local/lib/python3.8/site-packages/tensorflow/python/keras/wrappers/scikit_learn.py\", line 166, in fit\n",
      "    history = self.model.fit(x, y, **fit_args)\n",
      "  File \"/home/violeta/.local/lib/python3.8/site-packages/tensorflow/python/keras/engine/training.py\", line 1100, in fit\n",
      "    tmp_logs = self.train_function(iterator)\n",
      "  File \"/home/violeta/.local/lib/python3.8/site-packages/tensorflow/python/eager/def_function.py\", line 828, in __call__\n",
      "    result = self._call(*args, **kwds)\n",
      "  File \"/home/violeta/.local/lib/python3.8/site-packages/tensorflow/python/eager/def_function.py\", line 871, in _call\n",
      "    self._initialize(args, kwds, add_initializers_to=initializers)\n",
      "  File \"/home/violeta/.local/lib/python3.8/site-packages/tensorflow/python/eager/def_function.py\", line 725, in _initialize\n",
      "    self._stateful_fn._get_concrete_function_internal_garbage_collected(  # pylint: disable=protected-access\n",
      "  File \"/home/violeta/.local/lib/python3.8/site-packages/tensorflow/python/eager/function.py\", line 2969, in _get_concrete_function_internal_garbage_collected\n",
      "    graph_function, _ = self._maybe_define_function(args, kwargs)\n",
      "  File \"/home/violeta/.local/lib/python3.8/site-packages/tensorflow/python/eager/function.py\", line 3361, in _maybe_define_function\n",
      "    graph_function = self._create_graph_function(args, kwargs)\n",
      "  File \"/home/violeta/.local/lib/python3.8/site-packages/tensorflow/python/eager/function.py\", line 3196, in _create_graph_function\n",
      "    func_graph_module.func_graph_from_py_func(\n",
      "  File \"/home/violeta/.local/lib/python3.8/site-packages/tensorflow/python/framework/func_graph.py\", line 990, in func_graph_from_py_func\n",
      "    func_outputs = python_func(*func_args, **func_kwargs)\n",
      "  File \"/home/violeta/.local/lib/python3.8/site-packages/tensorflow/python/eager/def_function.py\", line 634, in wrapped_fn\n",
      "    out = weak_wrapped_fn().__wrapped__(*args, **kwds)\n",
      "  File \"/home/violeta/.local/lib/python3.8/site-packages/tensorflow/python/framework/func_graph.py\", line 977, in wrapper\n",
      "    raise e.ag_error_metadata.to_exception(e)\n",
      "ValueError: in user code:\n",
      "\n",
      "    /home/violeta/.local/lib/python3.8/site-packages/tensorflow/python/keras/engine/training.py:805 train_function  *\n",
      "        return step_function(self, iterator)\n",
      "    /home/violeta/.local/lib/python3.8/site-packages/tensorflow/python/keras/engine/training.py:795 step_function  **\n",
      "        outputs = model.distribute_strategy.run(run_step, args=(data,))\n",
      "    /home/violeta/.local/lib/python3.8/site-packages/tensorflow/python/distribute/distribute_lib.py:1259 run\n",
      "        return self._extended.call_for_each_replica(fn, args=args, kwargs=kwargs)\n",
      "    /home/violeta/.local/lib/python3.8/site-packages/tensorflow/python/distribute/distribute_lib.py:2730 call_for_each_replica\n",
      "        return self._call_for_each_replica(fn, args, kwargs)\n",
      "    /home/violeta/.local/lib/python3.8/site-packages/tensorflow/python/distribute/distribute_lib.py:3417 _call_for_each_replica\n",
      "        return fn(*args, **kwargs)\n",
      "    /home/violeta/.local/lib/python3.8/site-packages/tensorflow/python/keras/engine/training.py:788 run_step  **\n",
      "        outputs = model.train_step(data)\n",
      "    /home/violeta/.local/lib/python3.8/site-packages/tensorflow/python/keras/engine/training.py:754 train_step\n",
      "        y_pred = self(x, training=True)\n",
      "    /home/violeta/.local/lib/python3.8/site-packages/tensorflow/python/keras/engine/base_layer.py:998 __call__\n",
      "        input_spec.assert_input_compatibility(self.input_spec, inputs, self.name)\n",
      "    /home/violeta/.local/lib/python3.8/site-packages/tensorflow/python/keras/engine/input_spec.py:255 assert_input_compatibility\n",
      "        raise ValueError(\n",
      "\n",
      "    ValueError: Input 0 of layer sequential_2 is incompatible with the layer: expected axis -1 of input shape to have value 55 but received input with shape (None, 4281)\n",
      "\n",
      "\n",
      "  warnings.warn(\"Estimator fit failed. The score on this train-test\"\n",
      "/home/violeta/.local/lib/python3.8/site-packages/sklearn/model_selection/_validation.py:610: FitFailedWarning: Estimator fit failed. The score on this train-test partition for these parameters will be set to nan. Details: \n",
      "Traceback (most recent call last):\n",
      "  File \"/home/violeta/.local/lib/python3.8/site-packages/sklearn/model_selection/_validation.py\", line 593, in _fit_and_score\n",
      "    estimator.fit(X_train, y_train, **fit_params)\n",
      "  File \"/home/violeta/.local/lib/python3.8/site-packages/tensorflow/python/keras/wrappers/scikit_learn.py\", line 223, in fit\n",
      "    return super(KerasClassifier, self).fit(x, y, **kwargs)\n",
      "  File \"/home/violeta/.local/lib/python3.8/site-packages/tensorflow/python/keras/wrappers/scikit_learn.py\", line 166, in fit\n",
      "    history = self.model.fit(x, y, **fit_args)\n",
      "  File \"/home/violeta/.local/lib/python3.8/site-packages/tensorflow/python/keras/engine/training.py\", line 1100, in fit\n",
      "    tmp_logs = self.train_function(iterator)\n",
      "  File \"/home/violeta/.local/lib/python3.8/site-packages/tensorflow/python/eager/def_function.py\", line 828, in __call__\n",
      "    result = self._call(*args, **kwds)\n",
      "  File \"/home/violeta/.local/lib/python3.8/site-packages/tensorflow/python/eager/def_function.py\", line 871, in _call\n",
      "    self._initialize(args, kwds, add_initializers_to=initializers)\n",
      "  File \"/home/violeta/.local/lib/python3.8/site-packages/tensorflow/python/eager/def_function.py\", line 725, in _initialize\n",
      "    self._stateful_fn._get_concrete_function_internal_garbage_collected(  # pylint: disable=protected-access\n",
      "  File \"/home/violeta/.local/lib/python3.8/site-packages/tensorflow/python/eager/function.py\", line 2969, in _get_concrete_function_internal_garbage_collected\n",
      "    graph_function, _ = self._maybe_define_function(args, kwargs)\n",
      "  File \"/home/violeta/.local/lib/python3.8/site-packages/tensorflow/python/eager/function.py\", line 3361, in _maybe_define_function\n",
      "    graph_function = self._create_graph_function(args, kwargs)\n",
      "  File \"/home/violeta/.local/lib/python3.8/site-packages/tensorflow/python/eager/function.py\", line 3196, in _create_graph_function\n",
      "    func_graph_module.func_graph_from_py_func(\n",
      "  File \"/home/violeta/.local/lib/python3.8/site-packages/tensorflow/python/framework/func_graph.py\", line 990, in func_graph_from_py_func\n",
      "    func_outputs = python_func(*func_args, **func_kwargs)\n",
      "  File \"/home/violeta/.local/lib/python3.8/site-packages/tensorflow/python/eager/def_function.py\", line 634, in wrapped_fn\n",
      "    out = weak_wrapped_fn().__wrapped__(*args, **kwds)\n",
      "  File \"/home/violeta/.local/lib/python3.8/site-packages/tensorflow/python/framework/func_graph.py\", line 977, in wrapper\n",
      "    raise e.ag_error_metadata.to_exception(e)\n",
      "ValueError: in user code:\n",
      "\n",
      "    /home/violeta/.local/lib/python3.8/site-packages/tensorflow/python/keras/engine/training.py:805 train_function  *\n",
      "        return step_function(self, iterator)\n",
      "    /home/violeta/.local/lib/python3.8/site-packages/tensorflow/python/keras/engine/training.py:795 step_function  **\n",
      "        outputs = model.distribute_strategy.run(run_step, args=(data,))\n",
      "    /home/violeta/.local/lib/python3.8/site-packages/tensorflow/python/distribute/distribute_lib.py:1259 run\n",
      "        return self._extended.call_for_each_replica(fn, args=args, kwargs=kwargs)\n",
      "    /home/violeta/.local/lib/python3.8/site-packages/tensorflow/python/distribute/distribute_lib.py:2730 call_for_each_replica\n",
      "        return self._call_for_each_replica(fn, args, kwargs)\n",
      "    /home/violeta/.local/lib/python3.8/site-packages/tensorflow/python/distribute/distribute_lib.py:3417 _call_for_each_replica\n",
      "        return fn(*args, **kwargs)\n",
      "    /home/violeta/.local/lib/python3.8/site-packages/tensorflow/python/keras/engine/training.py:788 run_step  **\n",
      "        outputs = model.train_step(data)\n",
      "    /home/violeta/.local/lib/python3.8/site-packages/tensorflow/python/keras/engine/training.py:754 train_step\n",
      "        y_pred = self(x, training=True)\n",
      "    /home/violeta/.local/lib/python3.8/site-packages/tensorflow/python/keras/engine/base_layer.py:998 __call__\n",
      "        input_spec.assert_input_compatibility(self.input_spec, inputs, self.name)\n",
      "    /home/violeta/.local/lib/python3.8/site-packages/tensorflow/python/keras/engine/input_spec.py:255 assert_input_compatibility\n",
      "        raise ValueError(\n",
      "\n",
      "    ValueError: Input 0 of layer sequential_3 is incompatible with the layer: expected axis -1 of input shape to have value 55 but received input with shape (5, 4281)\n",
      "\n",
      "\n",
      "  warnings.warn(\"Estimator fit failed. The score on this train-test\"\n"
     ]
    },
    {
     "name": "stderr",
     "output_type": "stream",
     "text": [
      "/home/violeta/.local/lib/python3.8/site-packages/sklearn/model_selection/_validation.py:610: FitFailedWarning: Estimator fit failed. The score on this train-test partition for these parameters will be set to nan. Details: \n",
      "Traceback (most recent call last):\n",
      "  File \"/home/violeta/.local/lib/python3.8/site-packages/sklearn/model_selection/_validation.py\", line 593, in _fit_and_score\n",
      "    estimator.fit(X_train, y_train, **fit_params)\n",
      "  File \"/home/violeta/.local/lib/python3.8/site-packages/tensorflow/python/keras/wrappers/scikit_learn.py\", line 223, in fit\n",
      "    return super(KerasClassifier, self).fit(x, y, **kwargs)\n",
      "  File \"/home/violeta/.local/lib/python3.8/site-packages/tensorflow/python/keras/wrappers/scikit_learn.py\", line 166, in fit\n",
      "    history = self.model.fit(x, y, **fit_args)\n",
      "  File \"/home/violeta/.local/lib/python3.8/site-packages/tensorflow/python/keras/engine/training.py\", line 1100, in fit\n",
      "    tmp_logs = self.train_function(iterator)\n",
      "  File \"/home/violeta/.local/lib/python3.8/site-packages/tensorflow/python/eager/def_function.py\", line 828, in __call__\n",
      "    result = self._call(*args, **kwds)\n",
      "  File \"/home/violeta/.local/lib/python3.8/site-packages/tensorflow/python/eager/def_function.py\", line 871, in _call\n",
      "    self._initialize(args, kwds, add_initializers_to=initializers)\n",
      "  File \"/home/violeta/.local/lib/python3.8/site-packages/tensorflow/python/eager/def_function.py\", line 725, in _initialize\n",
      "    self._stateful_fn._get_concrete_function_internal_garbage_collected(  # pylint: disable=protected-access\n",
      "  File \"/home/violeta/.local/lib/python3.8/site-packages/tensorflow/python/eager/function.py\", line 2969, in _get_concrete_function_internal_garbage_collected\n",
      "    graph_function, _ = self._maybe_define_function(args, kwargs)\n",
      "  File \"/home/violeta/.local/lib/python3.8/site-packages/tensorflow/python/eager/function.py\", line 3361, in _maybe_define_function\n",
      "    graph_function = self._create_graph_function(args, kwargs)\n",
      "  File \"/home/violeta/.local/lib/python3.8/site-packages/tensorflow/python/eager/function.py\", line 3196, in _create_graph_function\n",
      "    func_graph_module.func_graph_from_py_func(\n",
      "  File \"/home/violeta/.local/lib/python3.8/site-packages/tensorflow/python/framework/func_graph.py\", line 990, in func_graph_from_py_func\n",
      "    func_outputs = python_func(*func_args, **func_kwargs)\n",
      "  File \"/home/violeta/.local/lib/python3.8/site-packages/tensorflow/python/eager/def_function.py\", line 634, in wrapped_fn\n",
      "    out = weak_wrapped_fn().__wrapped__(*args, **kwds)\n",
      "  File \"/home/violeta/.local/lib/python3.8/site-packages/tensorflow/python/framework/func_graph.py\", line 977, in wrapper\n",
      "    raise e.ag_error_metadata.to_exception(e)\n",
      "ValueError: in user code:\n",
      "\n",
      "    /home/violeta/.local/lib/python3.8/site-packages/tensorflow/python/keras/engine/training.py:805 train_function  *\n",
      "        return step_function(self, iterator)\n",
      "    /home/violeta/.local/lib/python3.8/site-packages/tensorflow/python/keras/engine/training.py:795 step_function  **\n",
      "        outputs = model.distribute_strategy.run(run_step, args=(data,))\n",
      "    /home/violeta/.local/lib/python3.8/site-packages/tensorflow/python/distribute/distribute_lib.py:1259 run\n",
      "        return self._extended.call_for_each_replica(fn, args=args, kwargs=kwargs)\n",
      "    /home/violeta/.local/lib/python3.8/site-packages/tensorflow/python/distribute/distribute_lib.py:2730 call_for_each_replica\n",
      "        return self._call_for_each_replica(fn, args, kwargs)\n",
      "    /home/violeta/.local/lib/python3.8/site-packages/tensorflow/python/distribute/distribute_lib.py:3417 _call_for_each_replica\n",
      "        return fn(*args, **kwargs)\n",
      "    /home/violeta/.local/lib/python3.8/site-packages/tensorflow/python/keras/engine/training.py:788 run_step  **\n",
      "        outputs = model.train_step(data)\n",
      "    /home/violeta/.local/lib/python3.8/site-packages/tensorflow/python/keras/engine/training.py:754 train_step\n",
      "        y_pred = self(x, training=True)\n",
      "    /home/violeta/.local/lib/python3.8/site-packages/tensorflow/python/keras/engine/base_layer.py:998 __call__\n",
      "        input_spec.assert_input_compatibility(self.input_spec, inputs, self.name)\n",
      "    /home/violeta/.local/lib/python3.8/site-packages/tensorflow/python/keras/engine/input_spec.py:255 assert_input_compatibility\n",
      "        raise ValueError(\n",
      "\n",
      "    ValueError: Input 0 of layer sequential_4 is incompatible with the layer: expected axis -1 of input shape to have value 55 but received input with shape (5, 4281)\n",
      "\n",
      "\n",
      "  warnings.warn(\"Estimator fit failed. The score on this train-test\"\n",
      "/home/violeta/.local/lib/python3.8/site-packages/sklearn/model_selection/_validation.py:610: FitFailedWarning: Estimator fit failed. The score on this train-test partition for these parameters will be set to nan. Details: \n",
      "Traceback (most recent call last):\n",
      "  File \"/home/violeta/.local/lib/python3.8/site-packages/sklearn/model_selection/_validation.py\", line 593, in _fit_and_score\n",
      "    estimator.fit(X_train, y_train, **fit_params)\n",
      "  File \"/home/violeta/.local/lib/python3.8/site-packages/tensorflow/python/keras/wrappers/scikit_learn.py\", line 223, in fit\n",
      "    return super(KerasClassifier, self).fit(x, y, **kwargs)\n",
      "  File \"/home/violeta/.local/lib/python3.8/site-packages/tensorflow/python/keras/wrappers/scikit_learn.py\", line 166, in fit\n",
      "    history = self.model.fit(x, y, **fit_args)\n",
      "  File \"/home/violeta/.local/lib/python3.8/site-packages/tensorflow/python/keras/engine/training.py\", line 1100, in fit\n",
      "    tmp_logs = self.train_function(iterator)\n",
      "  File \"/home/violeta/.local/lib/python3.8/site-packages/tensorflow/python/eager/def_function.py\", line 828, in __call__\n",
      "    result = self._call(*args, **kwds)\n",
      "  File \"/home/violeta/.local/lib/python3.8/site-packages/tensorflow/python/eager/def_function.py\", line 871, in _call\n",
      "    self._initialize(args, kwds, add_initializers_to=initializers)\n",
      "  File \"/home/violeta/.local/lib/python3.8/site-packages/tensorflow/python/eager/def_function.py\", line 725, in _initialize\n",
      "    self._stateful_fn._get_concrete_function_internal_garbage_collected(  # pylint: disable=protected-access\n",
      "  File \"/home/violeta/.local/lib/python3.8/site-packages/tensorflow/python/eager/function.py\", line 2969, in _get_concrete_function_internal_garbage_collected\n",
      "    graph_function, _ = self._maybe_define_function(args, kwargs)\n",
      "  File \"/home/violeta/.local/lib/python3.8/site-packages/tensorflow/python/eager/function.py\", line 3361, in _maybe_define_function\n",
      "    graph_function = self._create_graph_function(args, kwargs)\n",
      "  File \"/home/violeta/.local/lib/python3.8/site-packages/tensorflow/python/eager/function.py\", line 3196, in _create_graph_function\n",
      "    func_graph_module.func_graph_from_py_func(\n",
      "  File \"/home/violeta/.local/lib/python3.8/site-packages/tensorflow/python/framework/func_graph.py\", line 990, in func_graph_from_py_func\n",
      "    func_outputs = python_func(*func_args, **func_kwargs)\n",
      "  File \"/home/violeta/.local/lib/python3.8/site-packages/tensorflow/python/eager/def_function.py\", line 634, in wrapped_fn\n",
      "    out = weak_wrapped_fn().__wrapped__(*args, **kwds)\n",
      "  File \"/home/violeta/.local/lib/python3.8/site-packages/tensorflow/python/framework/func_graph.py\", line 977, in wrapper\n",
      "    raise e.ag_error_metadata.to_exception(e)\n",
      "ValueError: in user code:\n",
      "\n",
      "    /home/violeta/.local/lib/python3.8/site-packages/tensorflow/python/keras/engine/training.py:805 train_function  *\n",
      "        return step_function(self, iterator)\n",
      "    /home/violeta/.local/lib/python3.8/site-packages/tensorflow/python/keras/engine/training.py:795 step_function  **\n",
      "        outputs = model.distribute_strategy.run(run_step, args=(data,))\n",
      "    /home/violeta/.local/lib/python3.8/site-packages/tensorflow/python/distribute/distribute_lib.py:1259 run\n",
      "        return self._extended.call_for_each_replica(fn, args=args, kwargs=kwargs)\n",
      "    /home/violeta/.local/lib/python3.8/site-packages/tensorflow/python/distribute/distribute_lib.py:2730 call_for_each_replica\n",
      "        return self._call_for_each_replica(fn, args, kwargs)\n",
      "    /home/violeta/.local/lib/python3.8/site-packages/tensorflow/python/distribute/distribute_lib.py:3417 _call_for_each_replica\n",
      "        return fn(*args, **kwargs)\n",
      "    /home/violeta/.local/lib/python3.8/site-packages/tensorflow/python/keras/engine/training.py:788 run_step  **\n",
      "        outputs = model.train_step(data)\n",
      "    /home/violeta/.local/lib/python3.8/site-packages/tensorflow/python/keras/engine/training.py:754 train_step\n",
      "        y_pred = self(x, training=True)\n",
      "    /home/violeta/.local/lib/python3.8/site-packages/tensorflow/python/keras/engine/base_layer.py:998 __call__\n",
      "        input_spec.assert_input_compatibility(self.input_spec, inputs, self.name)\n",
      "    /home/violeta/.local/lib/python3.8/site-packages/tensorflow/python/keras/engine/input_spec.py:255 assert_input_compatibility\n",
      "        raise ValueError(\n",
      "\n",
      "    ValueError: Input 0 of layer sequential_5 is incompatible with the layer: expected axis -1 of input shape to have value 55 but received input with shape (None, 4281)\n",
      "\n",
      "\n",
      "  warnings.warn(\"Estimator fit failed. The score on this train-test\"\n"
     ]
    },
    {
     "name": "stderr",
     "output_type": "stream",
     "text": [
      "/home/violeta/.local/lib/python3.8/site-packages/sklearn/model_selection/_validation.py:610: FitFailedWarning: Estimator fit failed. The score on this train-test partition for these parameters will be set to nan. Details: \n",
      "Traceback (most recent call last):\n",
      "  File \"/home/violeta/.local/lib/python3.8/site-packages/sklearn/model_selection/_validation.py\", line 593, in _fit_and_score\n",
      "    estimator.fit(X_train, y_train, **fit_params)\n",
      "  File \"/home/violeta/.local/lib/python3.8/site-packages/tensorflow/python/keras/wrappers/scikit_learn.py\", line 223, in fit\n",
      "    return super(KerasClassifier, self).fit(x, y, **kwargs)\n",
      "  File \"/home/violeta/.local/lib/python3.8/site-packages/tensorflow/python/keras/wrappers/scikit_learn.py\", line 166, in fit\n",
      "    history = self.model.fit(x, y, **fit_args)\n",
      "  File \"/home/violeta/.local/lib/python3.8/site-packages/tensorflow/python/keras/engine/training.py\", line 1100, in fit\n",
      "    tmp_logs = self.train_function(iterator)\n",
      "  File \"/home/violeta/.local/lib/python3.8/site-packages/tensorflow/python/eager/def_function.py\", line 828, in __call__\n",
      "    result = self._call(*args, **kwds)\n",
      "  File \"/home/violeta/.local/lib/python3.8/site-packages/tensorflow/python/eager/def_function.py\", line 871, in _call\n",
      "    self._initialize(args, kwds, add_initializers_to=initializers)\n",
      "  File \"/home/violeta/.local/lib/python3.8/site-packages/tensorflow/python/eager/def_function.py\", line 725, in _initialize\n",
      "    self._stateful_fn._get_concrete_function_internal_garbage_collected(  # pylint: disable=protected-access\n",
      "  File \"/home/violeta/.local/lib/python3.8/site-packages/tensorflow/python/eager/function.py\", line 2969, in _get_concrete_function_internal_garbage_collected\n",
      "    graph_function, _ = self._maybe_define_function(args, kwargs)\n",
      "  File \"/home/violeta/.local/lib/python3.8/site-packages/tensorflow/python/eager/function.py\", line 3361, in _maybe_define_function\n",
      "    graph_function = self._create_graph_function(args, kwargs)\n",
      "  File \"/home/violeta/.local/lib/python3.8/site-packages/tensorflow/python/eager/function.py\", line 3196, in _create_graph_function\n",
      "    func_graph_module.func_graph_from_py_func(\n",
      "  File \"/home/violeta/.local/lib/python3.8/site-packages/tensorflow/python/framework/func_graph.py\", line 990, in func_graph_from_py_func\n",
      "    func_outputs = python_func(*func_args, **func_kwargs)\n",
      "  File \"/home/violeta/.local/lib/python3.8/site-packages/tensorflow/python/eager/def_function.py\", line 634, in wrapped_fn\n",
      "    out = weak_wrapped_fn().__wrapped__(*args, **kwds)\n",
      "  File \"/home/violeta/.local/lib/python3.8/site-packages/tensorflow/python/framework/func_graph.py\", line 977, in wrapper\n",
      "    raise e.ag_error_metadata.to_exception(e)\n",
      "ValueError: in user code:\n",
      "\n",
      "    /home/violeta/.local/lib/python3.8/site-packages/tensorflow/python/keras/engine/training.py:805 train_function  *\n",
      "        return step_function(self, iterator)\n",
      "    /home/violeta/.local/lib/python3.8/site-packages/tensorflow/python/keras/engine/training.py:795 step_function  **\n",
      "        outputs = model.distribute_strategy.run(run_step, args=(data,))\n",
      "    /home/violeta/.local/lib/python3.8/site-packages/tensorflow/python/distribute/distribute_lib.py:1259 run\n",
      "        return self._extended.call_for_each_replica(fn, args=args, kwargs=kwargs)\n",
      "    /home/violeta/.local/lib/python3.8/site-packages/tensorflow/python/distribute/distribute_lib.py:2730 call_for_each_replica\n",
      "        return self._call_for_each_replica(fn, args, kwargs)\n",
      "    /home/violeta/.local/lib/python3.8/site-packages/tensorflow/python/distribute/distribute_lib.py:3417 _call_for_each_replica\n",
      "        return fn(*args, **kwargs)\n",
      "    /home/violeta/.local/lib/python3.8/site-packages/tensorflow/python/keras/engine/training.py:788 run_step  **\n",
      "        outputs = model.train_step(data)\n",
      "    /home/violeta/.local/lib/python3.8/site-packages/tensorflow/python/keras/engine/training.py:754 train_step\n",
      "        y_pred = self(x, training=True)\n",
      "    /home/violeta/.local/lib/python3.8/site-packages/tensorflow/python/keras/engine/base_layer.py:998 __call__\n",
      "        input_spec.assert_input_compatibility(self.input_spec, inputs, self.name)\n",
      "    /home/violeta/.local/lib/python3.8/site-packages/tensorflow/python/keras/engine/input_spec.py:255 assert_input_compatibility\n",
      "        raise ValueError(\n",
      "\n",
      "    ValueError: Input 0 of layer sequential_6 is incompatible with the layer: expected axis -1 of input shape to have value 55 but received input with shape (None, 4281)\n",
      "\n",
      "\n",
      "  warnings.warn(\"Estimator fit failed. The score on this train-test\"\n",
      "/home/violeta/.local/lib/python3.8/site-packages/sklearn/model_selection/_validation.py:610: FitFailedWarning: Estimator fit failed. The score on this train-test partition for these parameters will be set to nan. Details: \n",
      "Traceback (most recent call last):\n",
      "  File \"/home/violeta/.local/lib/python3.8/site-packages/sklearn/model_selection/_validation.py\", line 593, in _fit_and_score\n",
      "    estimator.fit(X_train, y_train, **fit_params)\n",
      "  File \"/home/violeta/.local/lib/python3.8/site-packages/tensorflow/python/keras/wrappers/scikit_learn.py\", line 223, in fit\n",
      "    return super(KerasClassifier, self).fit(x, y, **kwargs)\n",
      "  File \"/home/violeta/.local/lib/python3.8/site-packages/tensorflow/python/keras/wrappers/scikit_learn.py\", line 166, in fit\n",
      "    history = self.model.fit(x, y, **fit_args)\n",
      "  File \"/home/violeta/.local/lib/python3.8/site-packages/tensorflow/python/keras/engine/training.py\", line 1100, in fit\n",
      "    tmp_logs = self.train_function(iterator)\n",
      "  File \"/home/violeta/.local/lib/python3.8/site-packages/tensorflow/python/eager/def_function.py\", line 828, in __call__\n",
      "    result = self._call(*args, **kwds)\n",
      "  File \"/home/violeta/.local/lib/python3.8/site-packages/tensorflow/python/eager/def_function.py\", line 871, in _call\n",
      "    self._initialize(args, kwds, add_initializers_to=initializers)\n",
      "  File \"/home/violeta/.local/lib/python3.8/site-packages/tensorflow/python/eager/def_function.py\", line 725, in _initialize\n",
      "    self._stateful_fn._get_concrete_function_internal_garbage_collected(  # pylint: disable=protected-access\n",
      "  File \"/home/violeta/.local/lib/python3.8/site-packages/tensorflow/python/eager/function.py\", line 2969, in _get_concrete_function_internal_garbage_collected\n",
      "    graph_function, _ = self._maybe_define_function(args, kwargs)\n",
      "  File \"/home/violeta/.local/lib/python3.8/site-packages/tensorflow/python/eager/function.py\", line 3361, in _maybe_define_function\n",
      "    graph_function = self._create_graph_function(args, kwargs)\n",
      "  File \"/home/violeta/.local/lib/python3.8/site-packages/tensorflow/python/eager/function.py\", line 3196, in _create_graph_function\n",
      "    func_graph_module.func_graph_from_py_func(\n",
      "  File \"/home/violeta/.local/lib/python3.8/site-packages/tensorflow/python/framework/func_graph.py\", line 990, in func_graph_from_py_func\n",
      "    func_outputs = python_func(*func_args, **func_kwargs)\n",
      "  File \"/home/violeta/.local/lib/python3.8/site-packages/tensorflow/python/eager/def_function.py\", line 634, in wrapped_fn\n",
      "    out = weak_wrapped_fn().__wrapped__(*args, **kwds)\n",
      "  File \"/home/violeta/.local/lib/python3.8/site-packages/tensorflow/python/framework/func_graph.py\", line 977, in wrapper\n",
      "    raise e.ag_error_metadata.to_exception(e)\n",
      "ValueError: in user code:\n",
      "\n",
      "    /home/violeta/.local/lib/python3.8/site-packages/tensorflow/python/keras/engine/training.py:805 train_function  *\n",
      "        return step_function(self, iterator)\n",
      "    /home/violeta/.local/lib/python3.8/site-packages/tensorflow/python/keras/engine/training.py:795 step_function  **\n",
      "        outputs = model.distribute_strategy.run(run_step, args=(data,))\n",
      "    /home/violeta/.local/lib/python3.8/site-packages/tensorflow/python/distribute/distribute_lib.py:1259 run\n",
      "        return self._extended.call_for_each_replica(fn, args=args, kwargs=kwargs)\n",
      "    /home/violeta/.local/lib/python3.8/site-packages/tensorflow/python/distribute/distribute_lib.py:2730 call_for_each_replica\n",
      "        return self._call_for_each_replica(fn, args, kwargs)\n",
      "    /home/violeta/.local/lib/python3.8/site-packages/tensorflow/python/distribute/distribute_lib.py:3417 _call_for_each_replica\n",
      "        return fn(*args, **kwargs)\n",
      "    /home/violeta/.local/lib/python3.8/site-packages/tensorflow/python/keras/engine/training.py:788 run_step  **\n",
      "        outputs = model.train_step(data)\n",
      "    /home/violeta/.local/lib/python3.8/site-packages/tensorflow/python/keras/engine/training.py:754 train_step\n",
      "        y_pred = self(x, training=True)\n",
      "    /home/violeta/.local/lib/python3.8/site-packages/tensorflow/python/keras/engine/base_layer.py:998 __call__\n",
      "        input_spec.assert_input_compatibility(self.input_spec, inputs, self.name)\n",
      "    /home/violeta/.local/lib/python3.8/site-packages/tensorflow/python/keras/engine/input_spec.py:255 assert_input_compatibility\n",
      "        raise ValueError(\n",
      "\n",
      "    ValueError: Input 0 of layer sequential_7 is incompatible with the layer: expected axis -1 of input shape to have value 55 but received input with shape (None, 4281)\n",
      "\n",
      "\n",
      "  warnings.warn(\"Estimator fit failed. The score on this train-test\"\n"
     ]
    },
    {
     "name": "stderr",
     "output_type": "stream",
     "text": [
      "/home/violeta/.local/lib/python3.8/site-packages/sklearn/model_selection/_validation.py:610: FitFailedWarning: Estimator fit failed. The score on this train-test partition for these parameters will be set to nan. Details: \n",
      "Traceback (most recent call last):\n",
      "  File \"/home/violeta/.local/lib/python3.8/site-packages/sklearn/model_selection/_validation.py\", line 593, in _fit_and_score\n",
      "    estimator.fit(X_train, y_train, **fit_params)\n",
      "  File \"/home/violeta/.local/lib/python3.8/site-packages/tensorflow/python/keras/wrappers/scikit_learn.py\", line 223, in fit\n",
      "    return super(KerasClassifier, self).fit(x, y, **kwargs)\n",
      "  File \"/home/violeta/.local/lib/python3.8/site-packages/tensorflow/python/keras/wrappers/scikit_learn.py\", line 166, in fit\n",
      "    history = self.model.fit(x, y, **fit_args)\n",
      "  File \"/home/violeta/.local/lib/python3.8/site-packages/tensorflow/python/keras/engine/training.py\", line 1100, in fit\n",
      "    tmp_logs = self.train_function(iterator)\n",
      "  File \"/home/violeta/.local/lib/python3.8/site-packages/tensorflow/python/eager/def_function.py\", line 828, in __call__\n",
      "    result = self._call(*args, **kwds)\n",
      "  File \"/home/violeta/.local/lib/python3.8/site-packages/tensorflow/python/eager/def_function.py\", line 871, in _call\n",
      "    self._initialize(args, kwds, add_initializers_to=initializers)\n",
      "  File \"/home/violeta/.local/lib/python3.8/site-packages/tensorflow/python/eager/def_function.py\", line 725, in _initialize\n",
      "    self._stateful_fn._get_concrete_function_internal_garbage_collected(  # pylint: disable=protected-access\n",
      "  File \"/home/violeta/.local/lib/python3.8/site-packages/tensorflow/python/eager/function.py\", line 2969, in _get_concrete_function_internal_garbage_collected\n",
      "    graph_function, _ = self._maybe_define_function(args, kwargs)\n",
      "  File \"/home/violeta/.local/lib/python3.8/site-packages/tensorflow/python/eager/function.py\", line 3361, in _maybe_define_function\n",
      "    graph_function = self._create_graph_function(args, kwargs)\n",
      "  File \"/home/violeta/.local/lib/python3.8/site-packages/tensorflow/python/eager/function.py\", line 3196, in _create_graph_function\n",
      "    func_graph_module.func_graph_from_py_func(\n",
      "  File \"/home/violeta/.local/lib/python3.8/site-packages/tensorflow/python/framework/func_graph.py\", line 990, in func_graph_from_py_func\n",
      "    func_outputs = python_func(*func_args, **func_kwargs)\n",
      "  File \"/home/violeta/.local/lib/python3.8/site-packages/tensorflow/python/eager/def_function.py\", line 634, in wrapped_fn\n",
      "    out = weak_wrapped_fn().__wrapped__(*args, **kwds)\n",
      "  File \"/home/violeta/.local/lib/python3.8/site-packages/tensorflow/python/framework/func_graph.py\", line 977, in wrapper\n",
      "    raise e.ag_error_metadata.to_exception(e)\n",
      "ValueError: in user code:\n",
      "\n",
      "    /home/violeta/.local/lib/python3.8/site-packages/tensorflow/python/keras/engine/training.py:805 train_function  *\n",
      "        return step_function(self, iterator)\n",
      "    /home/violeta/.local/lib/python3.8/site-packages/tensorflow/python/keras/engine/training.py:795 step_function  **\n",
      "        outputs = model.distribute_strategy.run(run_step, args=(data,))\n",
      "    /home/violeta/.local/lib/python3.8/site-packages/tensorflow/python/distribute/distribute_lib.py:1259 run\n",
      "        return self._extended.call_for_each_replica(fn, args=args, kwargs=kwargs)\n",
      "    /home/violeta/.local/lib/python3.8/site-packages/tensorflow/python/distribute/distribute_lib.py:2730 call_for_each_replica\n",
      "        return self._call_for_each_replica(fn, args, kwargs)\n",
      "    /home/violeta/.local/lib/python3.8/site-packages/tensorflow/python/distribute/distribute_lib.py:3417 _call_for_each_replica\n",
      "        return fn(*args, **kwargs)\n",
      "    /home/violeta/.local/lib/python3.8/site-packages/tensorflow/python/keras/engine/training.py:788 run_step  **\n",
      "        outputs = model.train_step(data)\n",
      "    /home/violeta/.local/lib/python3.8/site-packages/tensorflow/python/keras/engine/training.py:754 train_step\n",
      "        y_pred = self(x, training=True)\n",
      "    /home/violeta/.local/lib/python3.8/site-packages/tensorflow/python/keras/engine/base_layer.py:998 __call__\n",
      "        input_spec.assert_input_compatibility(self.input_spec, inputs, self.name)\n",
      "    /home/violeta/.local/lib/python3.8/site-packages/tensorflow/python/keras/engine/input_spec.py:255 assert_input_compatibility\n",
      "        raise ValueError(\n",
      "\n",
      "    ValueError: Input 0 of layer sequential_8 is incompatible with the layer: expected axis -1 of input shape to have value 55 but received input with shape (5, 4281)\n",
      "\n",
      "\n",
      "  warnings.warn(\"Estimator fit failed. The score on this train-test\"\n",
      "/home/violeta/.local/lib/python3.8/site-packages/sklearn/model_selection/_validation.py:610: FitFailedWarning: Estimator fit failed. The score on this train-test partition for these parameters will be set to nan. Details: \n",
      "Traceback (most recent call last):\n",
      "  File \"/home/violeta/.local/lib/python3.8/site-packages/sklearn/model_selection/_validation.py\", line 593, in _fit_and_score\n",
      "    estimator.fit(X_train, y_train, **fit_params)\n",
      "  File \"/home/violeta/.local/lib/python3.8/site-packages/tensorflow/python/keras/wrappers/scikit_learn.py\", line 223, in fit\n",
      "    return super(KerasClassifier, self).fit(x, y, **kwargs)\n",
      "  File \"/home/violeta/.local/lib/python3.8/site-packages/tensorflow/python/keras/wrappers/scikit_learn.py\", line 166, in fit\n",
      "    history = self.model.fit(x, y, **fit_args)\n",
      "  File \"/home/violeta/.local/lib/python3.8/site-packages/tensorflow/python/keras/engine/training.py\", line 1100, in fit\n",
      "    tmp_logs = self.train_function(iterator)\n",
      "  File \"/home/violeta/.local/lib/python3.8/site-packages/tensorflow/python/eager/def_function.py\", line 828, in __call__\n",
      "    result = self._call(*args, **kwds)\n",
      "  File \"/home/violeta/.local/lib/python3.8/site-packages/tensorflow/python/eager/def_function.py\", line 871, in _call\n",
      "    self._initialize(args, kwds, add_initializers_to=initializers)\n",
      "  File \"/home/violeta/.local/lib/python3.8/site-packages/tensorflow/python/eager/def_function.py\", line 725, in _initialize\n",
      "    self._stateful_fn._get_concrete_function_internal_garbage_collected(  # pylint: disable=protected-access\n",
      "  File \"/home/violeta/.local/lib/python3.8/site-packages/tensorflow/python/eager/function.py\", line 2969, in _get_concrete_function_internal_garbage_collected\n",
      "    graph_function, _ = self._maybe_define_function(args, kwargs)\n",
      "  File \"/home/violeta/.local/lib/python3.8/site-packages/tensorflow/python/eager/function.py\", line 3361, in _maybe_define_function\n",
      "    graph_function = self._create_graph_function(args, kwargs)\n",
      "  File \"/home/violeta/.local/lib/python3.8/site-packages/tensorflow/python/eager/function.py\", line 3196, in _create_graph_function\n",
      "    func_graph_module.func_graph_from_py_func(\n",
      "  File \"/home/violeta/.local/lib/python3.8/site-packages/tensorflow/python/framework/func_graph.py\", line 990, in func_graph_from_py_func\n",
      "    func_outputs = python_func(*func_args, **func_kwargs)\n",
      "  File \"/home/violeta/.local/lib/python3.8/site-packages/tensorflow/python/eager/def_function.py\", line 634, in wrapped_fn\n",
      "    out = weak_wrapped_fn().__wrapped__(*args, **kwds)\n",
      "  File \"/home/violeta/.local/lib/python3.8/site-packages/tensorflow/python/framework/func_graph.py\", line 977, in wrapper\n",
      "    raise e.ag_error_metadata.to_exception(e)\n",
      "ValueError: in user code:\n",
      "\n",
      "    /home/violeta/.local/lib/python3.8/site-packages/tensorflow/python/keras/engine/training.py:805 train_function  *\n",
      "        return step_function(self, iterator)\n",
      "    /home/violeta/.local/lib/python3.8/site-packages/tensorflow/python/keras/engine/training.py:795 step_function  **\n",
      "        outputs = model.distribute_strategy.run(run_step, args=(data,))\n",
      "    /home/violeta/.local/lib/python3.8/site-packages/tensorflow/python/distribute/distribute_lib.py:1259 run\n",
      "        return self._extended.call_for_each_replica(fn, args=args, kwargs=kwargs)\n",
      "    /home/violeta/.local/lib/python3.8/site-packages/tensorflow/python/distribute/distribute_lib.py:2730 call_for_each_replica\n",
      "        return self._call_for_each_replica(fn, args, kwargs)\n",
      "    /home/violeta/.local/lib/python3.8/site-packages/tensorflow/python/distribute/distribute_lib.py:3417 _call_for_each_replica\n",
      "        return fn(*args, **kwargs)\n",
      "    /home/violeta/.local/lib/python3.8/site-packages/tensorflow/python/keras/engine/training.py:788 run_step  **\n",
      "        outputs = model.train_step(data)\n",
      "    /home/violeta/.local/lib/python3.8/site-packages/tensorflow/python/keras/engine/training.py:754 train_step\n",
      "        y_pred = self(x, training=True)\n",
      "    /home/violeta/.local/lib/python3.8/site-packages/tensorflow/python/keras/engine/base_layer.py:998 __call__\n",
      "        input_spec.assert_input_compatibility(self.input_spec, inputs, self.name)\n",
      "    /home/violeta/.local/lib/python3.8/site-packages/tensorflow/python/keras/engine/input_spec.py:255 assert_input_compatibility\n",
      "        raise ValueError(\n",
      "\n",
      "    ValueError: Input 0 of layer sequential_9 is incompatible with the layer: expected axis -1 of input shape to have value 55 but received input with shape (5, 4281)\n",
      "\n",
      "\n",
      "  warnings.warn(\"Estimator fit failed. The score on this train-test\"\n"
     ]
    },
    {
     "name": "stderr",
     "output_type": "stream",
     "text": [
      "/home/violeta/.local/lib/python3.8/site-packages/sklearn/model_selection/_validation.py:610: FitFailedWarning: Estimator fit failed. The score on this train-test partition for these parameters will be set to nan. Details: \n",
      "Traceback (most recent call last):\n",
      "  File \"/home/violeta/.local/lib/python3.8/site-packages/sklearn/model_selection/_validation.py\", line 593, in _fit_and_score\n",
      "    estimator.fit(X_train, y_train, **fit_params)\n",
      "  File \"/home/violeta/.local/lib/python3.8/site-packages/tensorflow/python/keras/wrappers/scikit_learn.py\", line 223, in fit\n",
      "    return super(KerasClassifier, self).fit(x, y, **kwargs)\n",
      "  File \"/home/violeta/.local/lib/python3.8/site-packages/tensorflow/python/keras/wrappers/scikit_learn.py\", line 166, in fit\n",
      "    history = self.model.fit(x, y, **fit_args)\n",
      "  File \"/home/violeta/.local/lib/python3.8/site-packages/tensorflow/python/keras/engine/training.py\", line 1100, in fit\n",
      "    tmp_logs = self.train_function(iterator)\n",
      "  File \"/home/violeta/.local/lib/python3.8/site-packages/tensorflow/python/eager/def_function.py\", line 828, in __call__\n",
      "    result = self._call(*args, **kwds)\n",
      "  File \"/home/violeta/.local/lib/python3.8/site-packages/tensorflow/python/eager/def_function.py\", line 871, in _call\n",
      "    self._initialize(args, kwds, add_initializers_to=initializers)\n",
      "  File \"/home/violeta/.local/lib/python3.8/site-packages/tensorflow/python/eager/def_function.py\", line 725, in _initialize\n",
      "    self._stateful_fn._get_concrete_function_internal_garbage_collected(  # pylint: disable=protected-access\n",
      "  File \"/home/violeta/.local/lib/python3.8/site-packages/tensorflow/python/eager/function.py\", line 2969, in _get_concrete_function_internal_garbage_collected\n",
      "    graph_function, _ = self._maybe_define_function(args, kwargs)\n",
      "  File \"/home/violeta/.local/lib/python3.8/site-packages/tensorflow/python/eager/function.py\", line 3361, in _maybe_define_function\n",
      "    graph_function = self._create_graph_function(args, kwargs)\n",
      "  File \"/home/violeta/.local/lib/python3.8/site-packages/tensorflow/python/eager/function.py\", line 3196, in _create_graph_function\n",
      "    func_graph_module.func_graph_from_py_func(\n",
      "  File \"/home/violeta/.local/lib/python3.8/site-packages/tensorflow/python/framework/func_graph.py\", line 990, in func_graph_from_py_func\n",
      "    func_outputs = python_func(*func_args, **func_kwargs)\n",
      "  File \"/home/violeta/.local/lib/python3.8/site-packages/tensorflow/python/eager/def_function.py\", line 634, in wrapped_fn\n",
      "    out = weak_wrapped_fn().__wrapped__(*args, **kwds)\n",
      "  File \"/home/violeta/.local/lib/python3.8/site-packages/tensorflow/python/framework/func_graph.py\", line 977, in wrapper\n",
      "    raise e.ag_error_metadata.to_exception(e)\n",
      "ValueError: in user code:\n",
      "\n",
      "    /home/violeta/.local/lib/python3.8/site-packages/tensorflow/python/keras/engine/training.py:805 train_function  *\n",
      "        return step_function(self, iterator)\n",
      "    /home/violeta/.local/lib/python3.8/site-packages/tensorflow/python/keras/engine/training.py:795 step_function  **\n",
      "        outputs = model.distribute_strategy.run(run_step, args=(data,))\n",
      "    /home/violeta/.local/lib/python3.8/site-packages/tensorflow/python/distribute/distribute_lib.py:1259 run\n",
      "        return self._extended.call_for_each_replica(fn, args=args, kwargs=kwargs)\n",
      "    /home/violeta/.local/lib/python3.8/site-packages/tensorflow/python/distribute/distribute_lib.py:2730 call_for_each_replica\n",
      "        return self._call_for_each_replica(fn, args, kwargs)\n",
      "    /home/violeta/.local/lib/python3.8/site-packages/tensorflow/python/distribute/distribute_lib.py:3417 _call_for_each_replica\n",
      "        return fn(*args, **kwargs)\n",
      "    /home/violeta/.local/lib/python3.8/site-packages/tensorflow/python/keras/engine/training.py:788 run_step  **\n",
      "        outputs = model.train_step(data)\n",
      "    /home/violeta/.local/lib/python3.8/site-packages/tensorflow/python/keras/engine/training.py:754 train_step\n",
      "        y_pred = self(x, training=True)\n",
      "    /home/violeta/.local/lib/python3.8/site-packages/tensorflow/python/keras/engine/base_layer.py:998 __call__\n",
      "        input_spec.assert_input_compatibility(self.input_spec, inputs, self.name)\n",
      "    /home/violeta/.local/lib/python3.8/site-packages/tensorflow/python/keras/engine/input_spec.py:255 assert_input_compatibility\n",
      "        raise ValueError(\n",
      "\n",
      "    ValueError: Input 0 of layer sequential_10 is incompatible with the layer: expected axis -1 of input shape to have value 55 but received input with shape (None, 4281)\n",
      "\n",
      "\n",
      "  warnings.warn(\"Estimator fit failed. The score on this train-test\"\n",
      "/home/violeta/.local/lib/python3.8/site-packages/sklearn/model_selection/_validation.py:610: FitFailedWarning: Estimator fit failed. The score on this train-test partition for these parameters will be set to nan. Details: \n",
      "Traceback (most recent call last):\n",
      "  File \"/home/violeta/.local/lib/python3.8/site-packages/sklearn/model_selection/_validation.py\", line 593, in _fit_and_score\n",
      "    estimator.fit(X_train, y_train, **fit_params)\n",
      "  File \"/home/violeta/.local/lib/python3.8/site-packages/tensorflow/python/keras/wrappers/scikit_learn.py\", line 223, in fit\n",
      "    return super(KerasClassifier, self).fit(x, y, **kwargs)\n",
      "  File \"/home/violeta/.local/lib/python3.8/site-packages/tensorflow/python/keras/wrappers/scikit_learn.py\", line 166, in fit\n",
      "    history = self.model.fit(x, y, **fit_args)\n",
      "  File \"/home/violeta/.local/lib/python3.8/site-packages/tensorflow/python/keras/engine/training.py\", line 1100, in fit\n",
      "    tmp_logs = self.train_function(iterator)\n",
      "  File \"/home/violeta/.local/lib/python3.8/site-packages/tensorflow/python/eager/def_function.py\", line 828, in __call__\n",
      "    result = self._call(*args, **kwds)\n",
      "  File \"/home/violeta/.local/lib/python3.8/site-packages/tensorflow/python/eager/def_function.py\", line 871, in _call\n",
      "    self._initialize(args, kwds, add_initializers_to=initializers)\n",
      "  File \"/home/violeta/.local/lib/python3.8/site-packages/tensorflow/python/eager/def_function.py\", line 725, in _initialize\n",
      "    self._stateful_fn._get_concrete_function_internal_garbage_collected(  # pylint: disable=protected-access\n",
      "  File \"/home/violeta/.local/lib/python3.8/site-packages/tensorflow/python/eager/function.py\", line 2969, in _get_concrete_function_internal_garbage_collected\n",
      "    graph_function, _ = self._maybe_define_function(args, kwargs)\n",
      "  File \"/home/violeta/.local/lib/python3.8/site-packages/tensorflow/python/eager/function.py\", line 3361, in _maybe_define_function\n",
      "    graph_function = self._create_graph_function(args, kwargs)\n",
      "  File \"/home/violeta/.local/lib/python3.8/site-packages/tensorflow/python/eager/function.py\", line 3196, in _create_graph_function\n",
      "    func_graph_module.func_graph_from_py_func(\n",
      "  File \"/home/violeta/.local/lib/python3.8/site-packages/tensorflow/python/framework/func_graph.py\", line 990, in func_graph_from_py_func\n",
      "    func_outputs = python_func(*func_args, **func_kwargs)\n",
      "  File \"/home/violeta/.local/lib/python3.8/site-packages/tensorflow/python/eager/def_function.py\", line 634, in wrapped_fn\n",
      "    out = weak_wrapped_fn().__wrapped__(*args, **kwds)\n",
      "  File \"/home/violeta/.local/lib/python3.8/site-packages/tensorflow/python/framework/func_graph.py\", line 977, in wrapper\n",
      "    raise e.ag_error_metadata.to_exception(e)\n",
      "ValueError: in user code:\n",
      "\n",
      "    /home/violeta/.local/lib/python3.8/site-packages/tensorflow/python/keras/engine/training.py:805 train_function  *\n",
      "        return step_function(self, iterator)\n",
      "    /home/violeta/.local/lib/python3.8/site-packages/tensorflow/python/keras/engine/training.py:795 step_function  **\n",
      "        outputs = model.distribute_strategy.run(run_step, args=(data,))\n",
      "    /home/violeta/.local/lib/python3.8/site-packages/tensorflow/python/distribute/distribute_lib.py:1259 run\n",
      "        return self._extended.call_for_each_replica(fn, args=args, kwargs=kwargs)\n",
      "    /home/violeta/.local/lib/python3.8/site-packages/tensorflow/python/distribute/distribute_lib.py:2730 call_for_each_replica\n",
      "        return self._call_for_each_replica(fn, args, kwargs)\n",
      "    /home/violeta/.local/lib/python3.8/site-packages/tensorflow/python/distribute/distribute_lib.py:3417 _call_for_each_replica\n",
      "        return fn(*args, **kwargs)\n",
      "    /home/violeta/.local/lib/python3.8/site-packages/tensorflow/python/keras/engine/training.py:788 run_step  **\n",
      "        outputs = model.train_step(data)\n",
      "    /home/violeta/.local/lib/python3.8/site-packages/tensorflow/python/keras/engine/training.py:754 train_step\n",
      "        y_pred = self(x, training=True)\n",
      "    /home/violeta/.local/lib/python3.8/site-packages/tensorflow/python/keras/engine/base_layer.py:998 __call__\n",
      "        input_spec.assert_input_compatibility(self.input_spec, inputs, self.name)\n",
      "    /home/violeta/.local/lib/python3.8/site-packages/tensorflow/python/keras/engine/input_spec.py:255 assert_input_compatibility\n",
      "        raise ValueError(\n",
      "\n",
      "    ValueError: Input 0 of layer sequential_11 is incompatible with the layer: expected axis -1 of input shape to have value 55 but received input with shape (None, 4281)\n",
      "\n",
      "\n",
      "  warnings.warn(\"Estimator fit failed. The score on this train-test\"\n"
     ]
    },
    {
     "name": "stderr",
     "output_type": "stream",
     "text": [
      "/home/violeta/.local/lib/python3.8/site-packages/sklearn/model_selection/_validation.py:610: FitFailedWarning: Estimator fit failed. The score on this train-test partition for these parameters will be set to nan. Details: \n",
      "Traceback (most recent call last):\n",
      "  File \"/home/violeta/.local/lib/python3.8/site-packages/sklearn/model_selection/_validation.py\", line 593, in _fit_and_score\n",
      "    estimator.fit(X_train, y_train, **fit_params)\n",
      "  File \"/home/violeta/.local/lib/python3.8/site-packages/tensorflow/python/keras/wrappers/scikit_learn.py\", line 223, in fit\n",
      "    return super(KerasClassifier, self).fit(x, y, **kwargs)\n",
      "  File \"/home/violeta/.local/lib/python3.8/site-packages/tensorflow/python/keras/wrappers/scikit_learn.py\", line 166, in fit\n",
      "    history = self.model.fit(x, y, **fit_args)\n",
      "  File \"/home/violeta/.local/lib/python3.8/site-packages/tensorflow/python/keras/engine/training.py\", line 1100, in fit\n",
      "    tmp_logs = self.train_function(iterator)\n",
      "  File \"/home/violeta/.local/lib/python3.8/site-packages/tensorflow/python/eager/def_function.py\", line 828, in __call__\n",
      "    result = self._call(*args, **kwds)\n",
      "  File \"/home/violeta/.local/lib/python3.8/site-packages/tensorflow/python/eager/def_function.py\", line 871, in _call\n",
      "    self._initialize(args, kwds, add_initializers_to=initializers)\n",
      "  File \"/home/violeta/.local/lib/python3.8/site-packages/tensorflow/python/eager/def_function.py\", line 725, in _initialize\n",
      "    self._stateful_fn._get_concrete_function_internal_garbage_collected(  # pylint: disable=protected-access\n",
      "  File \"/home/violeta/.local/lib/python3.8/site-packages/tensorflow/python/eager/function.py\", line 2969, in _get_concrete_function_internal_garbage_collected\n",
      "    graph_function, _ = self._maybe_define_function(args, kwargs)\n",
      "  File \"/home/violeta/.local/lib/python3.8/site-packages/tensorflow/python/eager/function.py\", line 3361, in _maybe_define_function\n",
      "    graph_function = self._create_graph_function(args, kwargs)\n",
      "  File \"/home/violeta/.local/lib/python3.8/site-packages/tensorflow/python/eager/function.py\", line 3196, in _create_graph_function\n",
      "    func_graph_module.func_graph_from_py_func(\n",
      "  File \"/home/violeta/.local/lib/python3.8/site-packages/tensorflow/python/framework/func_graph.py\", line 990, in func_graph_from_py_func\n",
      "    func_outputs = python_func(*func_args, **func_kwargs)\n",
      "  File \"/home/violeta/.local/lib/python3.8/site-packages/tensorflow/python/eager/def_function.py\", line 634, in wrapped_fn\n",
      "    out = weak_wrapped_fn().__wrapped__(*args, **kwds)\n",
      "  File \"/home/violeta/.local/lib/python3.8/site-packages/tensorflow/python/framework/func_graph.py\", line 977, in wrapper\n",
      "    raise e.ag_error_metadata.to_exception(e)\n",
      "ValueError: in user code:\n",
      "\n",
      "    /home/violeta/.local/lib/python3.8/site-packages/tensorflow/python/keras/engine/training.py:805 train_function  *\n",
      "        return step_function(self, iterator)\n",
      "    /home/violeta/.local/lib/python3.8/site-packages/tensorflow/python/keras/engine/training.py:795 step_function  **\n",
      "        outputs = model.distribute_strategy.run(run_step, args=(data,))\n",
      "    /home/violeta/.local/lib/python3.8/site-packages/tensorflow/python/distribute/distribute_lib.py:1259 run\n",
      "        return self._extended.call_for_each_replica(fn, args=args, kwargs=kwargs)\n",
      "    /home/violeta/.local/lib/python3.8/site-packages/tensorflow/python/distribute/distribute_lib.py:2730 call_for_each_replica\n",
      "        return self._call_for_each_replica(fn, args, kwargs)\n",
      "    /home/violeta/.local/lib/python3.8/site-packages/tensorflow/python/distribute/distribute_lib.py:3417 _call_for_each_replica\n",
      "        return fn(*args, **kwargs)\n",
      "    /home/violeta/.local/lib/python3.8/site-packages/tensorflow/python/keras/engine/training.py:788 run_step  **\n",
      "        outputs = model.train_step(data)\n",
      "    /home/violeta/.local/lib/python3.8/site-packages/tensorflow/python/keras/engine/training.py:754 train_step\n",
      "        y_pred = self(x, training=True)\n",
      "    /home/violeta/.local/lib/python3.8/site-packages/tensorflow/python/keras/engine/base_layer.py:998 __call__\n",
      "        input_spec.assert_input_compatibility(self.input_spec, inputs, self.name)\n",
      "    /home/violeta/.local/lib/python3.8/site-packages/tensorflow/python/keras/engine/input_spec.py:255 assert_input_compatibility\n",
      "        raise ValueError(\n",
      "\n",
      "    ValueError: Input 0 of layer sequential_12 is incompatible with the layer: expected axis -1 of input shape to have value 55 but received input with shape (None, 4281)\n",
      "\n",
      "\n",
      "  warnings.warn(\"Estimator fit failed. The score on this train-test\"\n",
      "/home/violeta/.local/lib/python3.8/site-packages/sklearn/model_selection/_validation.py:610: FitFailedWarning: Estimator fit failed. The score on this train-test partition for these parameters will be set to nan. Details: \n",
      "Traceback (most recent call last):\n",
      "  File \"/home/violeta/.local/lib/python3.8/site-packages/sklearn/model_selection/_validation.py\", line 593, in _fit_and_score\n",
      "    estimator.fit(X_train, y_train, **fit_params)\n",
      "  File \"/home/violeta/.local/lib/python3.8/site-packages/tensorflow/python/keras/wrappers/scikit_learn.py\", line 223, in fit\n",
      "    return super(KerasClassifier, self).fit(x, y, **kwargs)\n",
      "  File \"/home/violeta/.local/lib/python3.8/site-packages/tensorflow/python/keras/wrappers/scikit_learn.py\", line 166, in fit\n",
      "    history = self.model.fit(x, y, **fit_args)\n",
      "  File \"/home/violeta/.local/lib/python3.8/site-packages/tensorflow/python/keras/engine/training.py\", line 1100, in fit\n",
      "    tmp_logs = self.train_function(iterator)\n",
      "  File \"/home/violeta/.local/lib/python3.8/site-packages/tensorflow/python/eager/def_function.py\", line 828, in __call__\n",
      "    result = self._call(*args, **kwds)\n",
      "  File \"/home/violeta/.local/lib/python3.8/site-packages/tensorflow/python/eager/def_function.py\", line 871, in _call\n",
      "    self._initialize(args, kwds, add_initializers_to=initializers)\n",
      "  File \"/home/violeta/.local/lib/python3.8/site-packages/tensorflow/python/eager/def_function.py\", line 725, in _initialize\n",
      "    self._stateful_fn._get_concrete_function_internal_garbage_collected(  # pylint: disable=protected-access\n",
      "  File \"/home/violeta/.local/lib/python3.8/site-packages/tensorflow/python/eager/function.py\", line 2969, in _get_concrete_function_internal_garbage_collected\n",
      "    graph_function, _ = self._maybe_define_function(args, kwargs)\n",
      "  File \"/home/violeta/.local/lib/python3.8/site-packages/tensorflow/python/eager/function.py\", line 3361, in _maybe_define_function\n",
      "    graph_function = self._create_graph_function(args, kwargs)\n",
      "  File \"/home/violeta/.local/lib/python3.8/site-packages/tensorflow/python/eager/function.py\", line 3196, in _create_graph_function\n",
      "    func_graph_module.func_graph_from_py_func(\n",
      "  File \"/home/violeta/.local/lib/python3.8/site-packages/tensorflow/python/framework/func_graph.py\", line 990, in func_graph_from_py_func\n",
      "    func_outputs = python_func(*func_args, **func_kwargs)\n",
      "  File \"/home/violeta/.local/lib/python3.8/site-packages/tensorflow/python/eager/def_function.py\", line 634, in wrapped_fn\n",
      "    out = weak_wrapped_fn().__wrapped__(*args, **kwds)\n",
      "  File \"/home/violeta/.local/lib/python3.8/site-packages/tensorflow/python/framework/func_graph.py\", line 977, in wrapper\n",
      "    raise e.ag_error_metadata.to_exception(e)\n",
      "ValueError: in user code:\n",
      "\n",
      "    /home/violeta/.local/lib/python3.8/site-packages/tensorflow/python/keras/engine/training.py:805 train_function  *\n",
      "        return step_function(self, iterator)\n",
      "    /home/violeta/.local/lib/python3.8/site-packages/tensorflow/python/keras/engine/training.py:795 step_function  **\n",
      "        outputs = model.distribute_strategy.run(run_step, args=(data,))\n",
      "    /home/violeta/.local/lib/python3.8/site-packages/tensorflow/python/distribute/distribute_lib.py:1259 run\n",
      "        return self._extended.call_for_each_replica(fn, args=args, kwargs=kwargs)\n",
      "    /home/violeta/.local/lib/python3.8/site-packages/tensorflow/python/distribute/distribute_lib.py:2730 call_for_each_replica\n",
      "        return self._call_for_each_replica(fn, args, kwargs)\n",
      "    /home/violeta/.local/lib/python3.8/site-packages/tensorflow/python/distribute/distribute_lib.py:3417 _call_for_each_replica\n",
      "        return fn(*args, **kwargs)\n",
      "    /home/violeta/.local/lib/python3.8/site-packages/tensorflow/python/keras/engine/training.py:788 run_step  **\n",
      "        outputs = model.train_step(data)\n",
      "    /home/violeta/.local/lib/python3.8/site-packages/tensorflow/python/keras/engine/training.py:754 train_step\n",
      "        y_pred = self(x, training=True)\n",
      "    /home/violeta/.local/lib/python3.8/site-packages/tensorflow/python/keras/engine/base_layer.py:998 __call__\n",
      "        input_spec.assert_input_compatibility(self.input_spec, inputs, self.name)\n",
      "    /home/violeta/.local/lib/python3.8/site-packages/tensorflow/python/keras/engine/input_spec.py:255 assert_input_compatibility\n",
      "        raise ValueError(\n",
      "\n",
      "    ValueError: Input 0 of layer sequential_13 is incompatible with the layer: expected axis -1 of input shape to have value 55 but received input with shape (5, 4281)\n",
      "\n",
      "\n",
      "  warnings.warn(\"Estimator fit failed. The score on this train-test\"\n"
     ]
    },
    {
     "name": "stderr",
     "output_type": "stream",
     "text": [
      "/home/violeta/.local/lib/python3.8/site-packages/sklearn/model_selection/_validation.py:610: FitFailedWarning: Estimator fit failed. The score on this train-test partition for these parameters will be set to nan. Details: \n",
      "Traceback (most recent call last):\n",
      "  File \"/home/violeta/.local/lib/python3.8/site-packages/sklearn/model_selection/_validation.py\", line 593, in _fit_and_score\n",
      "    estimator.fit(X_train, y_train, **fit_params)\n",
      "  File \"/home/violeta/.local/lib/python3.8/site-packages/tensorflow/python/keras/wrappers/scikit_learn.py\", line 223, in fit\n",
      "    return super(KerasClassifier, self).fit(x, y, **kwargs)\n",
      "  File \"/home/violeta/.local/lib/python3.8/site-packages/tensorflow/python/keras/wrappers/scikit_learn.py\", line 166, in fit\n",
      "    history = self.model.fit(x, y, **fit_args)\n",
      "  File \"/home/violeta/.local/lib/python3.8/site-packages/tensorflow/python/keras/engine/training.py\", line 1100, in fit\n",
      "    tmp_logs = self.train_function(iterator)\n",
      "  File \"/home/violeta/.local/lib/python3.8/site-packages/tensorflow/python/eager/def_function.py\", line 828, in __call__\n",
      "    result = self._call(*args, **kwds)\n",
      "  File \"/home/violeta/.local/lib/python3.8/site-packages/tensorflow/python/eager/def_function.py\", line 871, in _call\n",
      "    self._initialize(args, kwds, add_initializers_to=initializers)\n",
      "  File \"/home/violeta/.local/lib/python3.8/site-packages/tensorflow/python/eager/def_function.py\", line 725, in _initialize\n",
      "    self._stateful_fn._get_concrete_function_internal_garbage_collected(  # pylint: disable=protected-access\n",
      "  File \"/home/violeta/.local/lib/python3.8/site-packages/tensorflow/python/eager/function.py\", line 2969, in _get_concrete_function_internal_garbage_collected\n",
      "    graph_function, _ = self._maybe_define_function(args, kwargs)\n",
      "  File \"/home/violeta/.local/lib/python3.8/site-packages/tensorflow/python/eager/function.py\", line 3361, in _maybe_define_function\n",
      "    graph_function = self._create_graph_function(args, kwargs)\n",
      "  File \"/home/violeta/.local/lib/python3.8/site-packages/tensorflow/python/eager/function.py\", line 3196, in _create_graph_function\n",
      "    func_graph_module.func_graph_from_py_func(\n",
      "  File \"/home/violeta/.local/lib/python3.8/site-packages/tensorflow/python/framework/func_graph.py\", line 990, in func_graph_from_py_func\n",
      "    func_outputs = python_func(*func_args, **func_kwargs)\n",
      "  File \"/home/violeta/.local/lib/python3.8/site-packages/tensorflow/python/eager/def_function.py\", line 634, in wrapped_fn\n",
      "    out = weak_wrapped_fn().__wrapped__(*args, **kwds)\n",
      "  File \"/home/violeta/.local/lib/python3.8/site-packages/tensorflow/python/framework/func_graph.py\", line 977, in wrapper\n",
      "    raise e.ag_error_metadata.to_exception(e)\n",
      "ValueError: in user code:\n",
      "\n",
      "    /home/violeta/.local/lib/python3.8/site-packages/tensorflow/python/keras/engine/training.py:805 train_function  *\n",
      "        return step_function(self, iterator)\n",
      "    /home/violeta/.local/lib/python3.8/site-packages/tensorflow/python/keras/engine/training.py:795 step_function  **\n",
      "        outputs = model.distribute_strategy.run(run_step, args=(data,))\n",
      "    /home/violeta/.local/lib/python3.8/site-packages/tensorflow/python/distribute/distribute_lib.py:1259 run\n",
      "        return self._extended.call_for_each_replica(fn, args=args, kwargs=kwargs)\n",
      "    /home/violeta/.local/lib/python3.8/site-packages/tensorflow/python/distribute/distribute_lib.py:2730 call_for_each_replica\n",
      "        return self._call_for_each_replica(fn, args, kwargs)\n",
      "    /home/violeta/.local/lib/python3.8/site-packages/tensorflow/python/distribute/distribute_lib.py:3417 _call_for_each_replica\n",
      "        return fn(*args, **kwargs)\n",
      "    /home/violeta/.local/lib/python3.8/site-packages/tensorflow/python/keras/engine/training.py:788 run_step  **\n",
      "        outputs = model.train_step(data)\n",
      "    /home/violeta/.local/lib/python3.8/site-packages/tensorflow/python/keras/engine/training.py:754 train_step\n",
      "        y_pred = self(x, training=True)\n",
      "    /home/violeta/.local/lib/python3.8/site-packages/tensorflow/python/keras/engine/base_layer.py:998 __call__\n",
      "        input_spec.assert_input_compatibility(self.input_spec, inputs, self.name)\n",
      "    /home/violeta/.local/lib/python3.8/site-packages/tensorflow/python/keras/engine/input_spec.py:255 assert_input_compatibility\n",
      "        raise ValueError(\n",
      "\n",
      "    ValueError: Input 0 of layer sequential_14 is incompatible with the layer: expected axis -1 of input shape to have value 55 but received input with shape (5, 4281)\n",
      "\n",
      "\n",
      "  warnings.warn(\"Estimator fit failed. The score on this train-test\"\n",
      "/home/violeta/.local/lib/python3.8/site-packages/sklearn/model_selection/_validation.py:610: FitFailedWarning: Estimator fit failed. The score on this train-test partition for these parameters will be set to nan. Details: \n",
      "Traceback (most recent call last):\n",
      "  File \"/home/violeta/.local/lib/python3.8/site-packages/sklearn/model_selection/_validation.py\", line 593, in _fit_and_score\n",
      "    estimator.fit(X_train, y_train, **fit_params)\n",
      "  File \"/home/violeta/.local/lib/python3.8/site-packages/tensorflow/python/keras/wrappers/scikit_learn.py\", line 223, in fit\n",
      "    return super(KerasClassifier, self).fit(x, y, **kwargs)\n",
      "  File \"/home/violeta/.local/lib/python3.8/site-packages/tensorflow/python/keras/wrappers/scikit_learn.py\", line 166, in fit\n",
      "    history = self.model.fit(x, y, **fit_args)\n",
      "  File \"/home/violeta/.local/lib/python3.8/site-packages/tensorflow/python/keras/engine/training.py\", line 1100, in fit\n",
      "    tmp_logs = self.train_function(iterator)\n",
      "  File \"/home/violeta/.local/lib/python3.8/site-packages/tensorflow/python/eager/def_function.py\", line 828, in __call__\n",
      "    result = self._call(*args, **kwds)\n",
      "  File \"/home/violeta/.local/lib/python3.8/site-packages/tensorflow/python/eager/def_function.py\", line 871, in _call\n",
      "    self._initialize(args, kwds, add_initializers_to=initializers)\n",
      "  File \"/home/violeta/.local/lib/python3.8/site-packages/tensorflow/python/eager/def_function.py\", line 725, in _initialize\n",
      "    self._stateful_fn._get_concrete_function_internal_garbage_collected(  # pylint: disable=protected-access\n",
      "  File \"/home/violeta/.local/lib/python3.8/site-packages/tensorflow/python/eager/function.py\", line 2969, in _get_concrete_function_internal_garbage_collected\n",
      "    graph_function, _ = self._maybe_define_function(args, kwargs)\n",
      "  File \"/home/violeta/.local/lib/python3.8/site-packages/tensorflow/python/eager/function.py\", line 3361, in _maybe_define_function\n",
      "    graph_function = self._create_graph_function(args, kwargs)\n",
      "  File \"/home/violeta/.local/lib/python3.8/site-packages/tensorflow/python/eager/function.py\", line 3196, in _create_graph_function\n",
      "    func_graph_module.func_graph_from_py_func(\n",
      "  File \"/home/violeta/.local/lib/python3.8/site-packages/tensorflow/python/framework/func_graph.py\", line 990, in func_graph_from_py_func\n",
      "    func_outputs = python_func(*func_args, **func_kwargs)\n",
      "  File \"/home/violeta/.local/lib/python3.8/site-packages/tensorflow/python/eager/def_function.py\", line 634, in wrapped_fn\n",
      "    out = weak_wrapped_fn().__wrapped__(*args, **kwds)\n",
      "  File \"/home/violeta/.local/lib/python3.8/site-packages/tensorflow/python/framework/func_graph.py\", line 977, in wrapper\n",
      "    raise e.ag_error_metadata.to_exception(e)\n",
      "ValueError: in user code:\n",
      "\n",
      "    /home/violeta/.local/lib/python3.8/site-packages/tensorflow/python/keras/engine/training.py:805 train_function  *\n",
      "        return step_function(self, iterator)\n",
      "    /home/violeta/.local/lib/python3.8/site-packages/tensorflow/python/keras/engine/training.py:795 step_function  **\n",
      "        outputs = model.distribute_strategy.run(run_step, args=(data,))\n",
      "    /home/violeta/.local/lib/python3.8/site-packages/tensorflow/python/distribute/distribute_lib.py:1259 run\n",
      "        return self._extended.call_for_each_replica(fn, args=args, kwargs=kwargs)\n",
      "    /home/violeta/.local/lib/python3.8/site-packages/tensorflow/python/distribute/distribute_lib.py:2730 call_for_each_replica\n",
      "        return self._call_for_each_replica(fn, args, kwargs)\n",
      "    /home/violeta/.local/lib/python3.8/site-packages/tensorflow/python/distribute/distribute_lib.py:3417 _call_for_each_replica\n",
      "        return fn(*args, **kwargs)\n",
      "    /home/violeta/.local/lib/python3.8/site-packages/tensorflow/python/keras/engine/training.py:788 run_step  **\n",
      "        outputs = model.train_step(data)\n",
      "    /home/violeta/.local/lib/python3.8/site-packages/tensorflow/python/keras/engine/training.py:754 train_step\n",
      "        y_pred = self(x, training=True)\n",
      "    /home/violeta/.local/lib/python3.8/site-packages/tensorflow/python/keras/engine/base_layer.py:998 __call__\n",
      "        input_spec.assert_input_compatibility(self.input_spec, inputs, self.name)\n",
      "    /home/violeta/.local/lib/python3.8/site-packages/tensorflow/python/keras/engine/input_spec.py:255 assert_input_compatibility\n",
      "        raise ValueError(\n",
      "\n",
      "    ValueError: Input 0 of layer sequential_15 is incompatible with the layer: expected axis -1 of input shape to have value 55 but received input with shape (None, 4281)\n",
      "\n",
      "\n",
      "  warnings.warn(\"Estimator fit failed. The score on this train-test\"\n"
     ]
    },
    {
     "name": "stderr",
     "output_type": "stream",
     "text": [
      "/home/violeta/.local/lib/python3.8/site-packages/sklearn/model_selection/_validation.py:610: FitFailedWarning: Estimator fit failed. The score on this train-test partition for these parameters will be set to nan. Details: \n",
      "Traceback (most recent call last):\n",
      "  File \"/home/violeta/.local/lib/python3.8/site-packages/sklearn/model_selection/_validation.py\", line 593, in _fit_and_score\n",
      "    estimator.fit(X_train, y_train, **fit_params)\n",
      "  File \"/home/violeta/.local/lib/python3.8/site-packages/tensorflow/python/keras/wrappers/scikit_learn.py\", line 223, in fit\n",
      "    return super(KerasClassifier, self).fit(x, y, **kwargs)\n",
      "  File \"/home/violeta/.local/lib/python3.8/site-packages/tensorflow/python/keras/wrappers/scikit_learn.py\", line 166, in fit\n",
      "    history = self.model.fit(x, y, **fit_args)\n",
      "  File \"/home/violeta/.local/lib/python3.8/site-packages/tensorflow/python/keras/engine/training.py\", line 1100, in fit\n",
      "    tmp_logs = self.train_function(iterator)\n",
      "  File \"/home/violeta/.local/lib/python3.8/site-packages/tensorflow/python/eager/def_function.py\", line 828, in __call__\n",
      "    result = self._call(*args, **kwds)\n",
      "  File \"/home/violeta/.local/lib/python3.8/site-packages/tensorflow/python/eager/def_function.py\", line 871, in _call\n",
      "    self._initialize(args, kwds, add_initializers_to=initializers)\n",
      "  File \"/home/violeta/.local/lib/python3.8/site-packages/tensorflow/python/eager/def_function.py\", line 725, in _initialize\n",
      "    self._stateful_fn._get_concrete_function_internal_garbage_collected(  # pylint: disable=protected-access\n",
      "  File \"/home/violeta/.local/lib/python3.8/site-packages/tensorflow/python/eager/function.py\", line 2969, in _get_concrete_function_internal_garbage_collected\n",
      "    graph_function, _ = self._maybe_define_function(args, kwargs)\n",
      "  File \"/home/violeta/.local/lib/python3.8/site-packages/tensorflow/python/eager/function.py\", line 3361, in _maybe_define_function\n",
      "    graph_function = self._create_graph_function(args, kwargs)\n",
      "  File \"/home/violeta/.local/lib/python3.8/site-packages/tensorflow/python/eager/function.py\", line 3196, in _create_graph_function\n",
      "    func_graph_module.func_graph_from_py_func(\n",
      "  File \"/home/violeta/.local/lib/python3.8/site-packages/tensorflow/python/framework/func_graph.py\", line 990, in func_graph_from_py_func\n",
      "    func_outputs = python_func(*func_args, **func_kwargs)\n",
      "  File \"/home/violeta/.local/lib/python3.8/site-packages/tensorflow/python/eager/def_function.py\", line 634, in wrapped_fn\n",
      "    out = weak_wrapped_fn().__wrapped__(*args, **kwds)\n",
      "  File \"/home/violeta/.local/lib/python3.8/site-packages/tensorflow/python/framework/func_graph.py\", line 977, in wrapper\n",
      "    raise e.ag_error_metadata.to_exception(e)\n",
      "ValueError: in user code:\n",
      "\n",
      "    /home/violeta/.local/lib/python3.8/site-packages/tensorflow/python/keras/engine/training.py:805 train_function  *\n",
      "        return step_function(self, iterator)\n",
      "    /home/violeta/.local/lib/python3.8/site-packages/tensorflow/python/keras/engine/training.py:795 step_function  **\n",
      "        outputs = model.distribute_strategy.run(run_step, args=(data,))\n",
      "    /home/violeta/.local/lib/python3.8/site-packages/tensorflow/python/distribute/distribute_lib.py:1259 run\n",
      "        return self._extended.call_for_each_replica(fn, args=args, kwargs=kwargs)\n",
      "    /home/violeta/.local/lib/python3.8/site-packages/tensorflow/python/distribute/distribute_lib.py:2730 call_for_each_replica\n",
      "        return self._call_for_each_replica(fn, args, kwargs)\n",
      "    /home/violeta/.local/lib/python3.8/site-packages/tensorflow/python/distribute/distribute_lib.py:3417 _call_for_each_replica\n",
      "        return fn(*args, **kwargs)\n",
      "    /home/violeta/.local/lib/python3.8/site-packages/tensorflow/python/keras/engine/training.py:788 run_step  **\n",
      "        outputs = model.train_step(data)\n",
      "    /home/violeta/.local/lib/python3.8/site-packages/tensorflow/python/keras/engine/training.py:754 train_step\n",
      "        y_pred = self(x, training=True)\n",
      "    /home/violeta/.local/lib/python3.8/site-packages/tensorflow/python/keras/engine/base_layer.py:998 __call__\n",
      "        input_spec.assert_input_compatibility(self.input_spec, inputs, self.name)\n",
      "    /home/violeta/.local/lib/python3.8/site-packages/tensorflow/python/keras/engine/input_spec.py:255 assert_input_compatibility\n",
      "        raise ValueError(\n",
      "\n",
      "    ValueError: Input 0 of layer sequential_16 is incompatible with the layer: expected axis -1 of input shape to have value 55 but received input with shape (None, 4281)\n",
      "\n",
      "\n",
      "  warnings.warn(\"Estimator fit failed. The score on this train-test\"\n",
      "/home/violeta/.local/lib/python3.8/site-packages/sklearn/model_selection/_validation.py:610: FitFailedWarning: Estimator fit failed. The score on this train-test partition for these parameters will be set to nan. Details: \n",
      "Traceback (most recent call last):\n",
      "  File \"/home/violeta/.local/lib/python3.8/site-packages/sklearn/model_selection/_validation.py\", line 593, in _fit_and_score\n",
      "    estimator.fit(X_train, y_train, **fit_params)\n",
      "  File \"/home/violeta/.local/lib/python3.8/site-packages/tensorflow/python/keras/wrappers/scikit_learn.py\", line 223, in fit\n",
      "    return super(KerasClassifier, self).fit(x, y, **kwargs)\n",
      "  File \"/home/violeta/.local/lib/python3.8/site-packages/tensorflow/python/keras/wrappers/scikit_learn.py\", line 166, in fit\n",
      "    history = self.model.fit(x, y, **fit_args)\n",
      "  File \"/home/violeta/.local/lib/python3.8/site-packages/tensorflow/python/keras/engine/training.py\", line 1100, in fit\n",
      "    tmp_logs = self.train_function(iterator)\n",
      "  File \"/home/violeta/.local/lib/python3.8/site-packages/tensorflow/python/eager/def_function.py\", line 828, in __call__\n",
      "    result = self._call(*args, **kwds)\n",
      "  File \"/home/violeta/.local/lib/python3.8/site-packages/tensorflow/python/eager/def_function.py\", line 871, in _call\n",
      "    self._initialize(args, kwds, add_initializers_to=initializers)\n",
      "  File \"/home/violeta/.local/lib/python3.8/site-packages/tensorflow/python/eager/def_function.py\", line 725, in _initialize\n",
      "    self._stateful_fn._get_concrete_function_internal_garbage_collected(  # pylint: disable=protected-access\n",
      "  File \"/home/violeta/.local/lib/python3.8/site-packages/tensorflow/python/eager/function.py\", line 2969, in _get_concrete_function_internal_garbage_collected\n",
      "    graph_function, _ = self._maybe_define_function(args, kwargs)\n",
      "  File \"/home/violeta/.local/lib/python3.8/site-packages/tensorflow/python/eager/function.py\", line 3361, in _maybe_define_function\n",
      "    graph_function = self._create_graph_function(args, kwargs)\n",
      "  File \"/home/violeta/.local/lib/python3.8/site-packages/tensorflow/python/eager/function.py\", line 3196, in _create_graph_function\n",
      "    func_graph_module.func_graph_from_py_func(\n",
      "  File \"/home/violeta/.local/lib/python3.8/site-packages/tensorflow/python/framework/func_graph.py\", line 990, in func_graph_from_py_func\n",
      "    func_outputs = python_func(*func_args, **func_kwargs)\n",
      "  File \"/home/violeta/.local/lib/python3.8/site-packages/tensorflow/python/eager/def_function.py\", line 634, in wrapped_fn\n",
      "    out = weak_wrapped_fn().__wrapped__(*args, **kwds)\n",
      "  File \"/home/violeta/.local/lib/python3.8/site-packages/tensorflow/python/framework/func_graph.py\", line 977, in wrapper\n",
      "    raise e.ag_error_metadata.to_exception(e)\n",
      "ValueError: in user code:\n",
      "\n",
      "    /home/violeta/.local/lib/python3.8/site-packages/tensorflow/python/keras/engine/training.py:805 train_function  *\n",
      "        return step_function(self, iterator)\n",
      "    /home/violeta/.local/lib/python3.8/site-packages/tensorflow/python/keras/engine/training.py:795 step_function  **\n",
      "        outputs = model.distribute_strategy.run(run_step, args=(data,))\n",
      "    /home/violeta/.local/lib/python3.8/site-packages/tensorflow/python/distribute/distribute_lib.py:1259 run\n",
      "        return self._extended.call_for_each_replica(fn, args=args, kwargs=kwargs)\n",
      "    /home/violeta/.local/lib/python3.8/site-packages/tensorflow/python/distribute/distribute_lib.py:2730 call_for_each_replica\n",
      "        return self._call_for_each_replica(fn, args, kwargs)\n",
      "    /home/violeta/.local/lib/python3.8/site-packages/tensorflow/python/distribute/distribute_lib.py:3417 _call_for_each_replica\n",
      "        return fn(*args, **kwargs)\n",
      "    /home/violeta/.local/lib/python3.8/site-packages/tensorflow/python/keras/engine/training.py:788 run_step  **\n",
      "        outputs = model.train_step(data)\n",
      "    /home/violeta/.local/lib/python3.8/site-packages/tensorflow/python/keras/engine/training.py:754 train_step\n",
      "        y_pred = self(x, training=True)\n",
      "    /home/violeta/.local/lib/python3.8/site-packages/tensorflow/python/keras/engine/base_layer.py:998 __call__\n",
      "        input_spec.assert_input_compatibility(self.input_spec, inputs, self.name)\n",
      "    /home/violeta/.local/lib/python3.8/site-packages/tensorflow/python/keras/engine/input_spec.py:255 assert_input_compatibility\n",
      "        raise ValueError(\n",
      "\n",
      "    ValueError: Input 0 of layer sequential_17 is incompatible with the layer: expected axis -1 of input shape to have value 55 but received input with shape (None, 4281)\n",
      "\n",
      "\n",
      "  warnings.warn(\"Estimator fit failed. The score on this train-test\"\n"
     ]
    },
    {
     "name": "stderr",
     "output_type": "stream",
     "text": [
      "/home/violeta/.local/lib/python3.8/site-packages/sklearn/model_selection/_validation.py:610: FitFailedWarning: Estimator fit failed. The score on this train-test partition for these parameters will be set to nan. Details: \n",
      "Traceback (most recent call last):\n",
      "  File \"/home/violeta/.local/lib/python3.8/site-packages/sklearn/model_selection/_validation.py\", line 593, in _fit_and_score\n",
      "    estimator.fit(X_train, y_train, **fit_params)\n",
      "  File \"/home/violeta/.local/lib/python3.8/site-packages/tensorflow/python/keras/wrappers/scikit_learn.py\", line 223, in fit\n",
      "    return super(KerasClassifier, self).fit(x, y, **kwargs)\n",
      "  File \"/home/violeta/.local/lib/python3.8/site-packages/tensorflow/python/keras/wrappers/scikit_learn.py\", line 166, in fit\n",
      "    history = self.model.fit(x, y, **fit_args)\n",
      "  File \"/home/violeta/.local/lib/python3.8/site-packages/tensorflow/python/keras/engine/training.py\", line 1100, in fit\n",
      "    tmp_logs = self.train_function(iterator)\n",
      "  File \"/home/violeta/.local/lib/python3.8/site-packages/tensorflow/python/eager/def_function.py\", line 828, in __call__\n",
      "    result = self._call(*args, **kwds)\n",
      "  File \"/home/violeta/.local/lib/python3.8/site-packages/tensorflow/python/eager/def_function.py\", line 871, in _call\n",
      "    self._initialize(args, kwds, add_initializers_to=initializers)\n",
      "  File \"/home/violeta/.local/lib/python3.8/site-packages/tensorflow/python/eager/def_function.py\", line 725, in _initialize\n",
      "    self._stateful_fn._get_concrete_function_internal_garbage_collected(  # pylint: disable=protected-access\n",
      "  File \"/home/violeta/.local/lib/python3.8/site-packages/tensorflow/python/eager/function.py\", line 2969, in _get_concrete_function_internal_garbage_collected\n",
      "    graph_function, _ = self._maybe_define_function(args, kwargs)\n",
      "  File \"/home/violeta/.local/lib/python3.8/site-packages/tensorflow/python/eager/function.py\", line 3361, in _maybe_define_function\n",
      "    graph_function = self._create_graph_function(args, kwargs)\n",
      "  File \"/home/violeta/.local/lib/python3.8/site-packages/tensorflow/python/eager/function.py\", line 3196, in _create_graph_function\n",
      "    func_graph_module.func_graph_from_py_func(\n",
      "  File \"/home/violeta/.local/lib/python3.8/site-packages/tensorflow/python/framework/func_graph.py\", line 990, in func_graph_from_py_func\n",
      "    func_outputs = python_func(*func_args, **func_kwargs)\n",
      "  File \"/home/violeta/.local/lib/python3.8/site-packages/tensorflow/python/eager/def_function.py\", line 634, in wrapped_fn\n",
      "    out = weak_wrapped_fn().__wrapped__(*args, **kwds)\n",
      "  File \"/home/violeta/.local/lib/python3.8/site-packages/tensorflow/python/framework/func_graph.py\", line 977, in wrapper\n",
      "    raise e.ag_error_metadata.to_exception(e)\n",
      "ValueError: in user code:\n",
      "\n",
      "    /home/violeta/.local/lib/python3.8/site-packages/tensorflow/python/keras/engine/training.py:805 train_function  *\n",
      "        return step_function(self, iterator)\n",
      "    /home/violeta/.local/lib/python3.8/site-packages/tensorflow/python/keras/engine/training.py:795 step_function  **\n",
      "        outputs = model.distribute_strategy.run(run_step, args=(data,))\n",
      "    /home/violeta/.local/lib/python3.8/site-packages/tensorflow/python/distribute/distribute_lib.py:1259 run\n",
      "        return self._extended.call_for_each_replica(fn, args=args, kwargs=kwargs)\n",
      "    /home/violeta/.local/lib/python3.8/site-packages/tensorflow/python/distribute/distribute_lib.py:2730 call_for_each_replica\n",
      "        return self._call_for_each_replica(fn, args, kwargs)\n",
      "    /home/violeta/.local/lib/python3.8/site-packages/tensorflow/python/distribute/distribute_lib.py:3417 _call_for_each_replica\n",
      "        return fn(*args, **kwargs)\n",
      "    /home/violeta/.local/lib/python3.8/site-packages/tensorflow/python/keras/engine/training.py:788 run_step  **\n",
      "        outputs = model.train_step(data)\n",
      "    /home/violeta/.local/lib/python3.8/site-packages/tensorflow/python/keras/engine/training.py:754 train_step\n",
      "        y_pred = self(x, training=True)\n",
      "    /home/violeta/.local/lib/python3.8/site-packages/tensorflow/python/keras/engine/base_layer.py:998 __call__\n",
      "        input_spec.assert_input_compatibility(self.input_spec, inputs, self.name)\n",
      "    /home/violeta/.local/lib/python3.8/site-packages/tensorflow/python/keras/engine/input_spec.py:255 assert_input_compatibility\n",
      "        raise ValueError(\n",
      "\n",
      "    ValueError: Input 0 of layer sequential_18 is incompatible with the layer: expected axis -1 of input shape to have value 55 but received input with shape (5, 4281)\n",
      "\n",
      "\n",
      "  warnings.warn(\"Estimator fit failed. The score on this train-test\"\n",
      "/home/violeta/.local/lib/python3.8/site-packages/sklearn/model_selection/_validation.py:610: FitFailedWarning: Estimator fit failed. The score on this train-test partition for these parameters will be set to nan. Details: \n",
      "Traceback (most recent call last):\n",
      "  File \"/home/violeta/.local/lib/python3.8/site-packages/sklearn/model_selection/_validation.py\", line 593, in _fit_and_score\n",
      "    estimator.fit(X_train, y_train, **fit_params)\n",
      "  File \"/home/violeta/.local/lib/python3.8/site-packages/tensorflow/python/keras/wrappers/scikit_learn.py\", line 223, in fit\n",
      "    return super(KerasClassifier, self).fit(x, y, **kwargs)\n",
      "  File \"/home/violeta/.local/lib/python3.8/site-packages/tensorflow/python/keras/wrappers/scikit_learn.py\", line 166, in fit\n",
      "    history = self.model.fit(x, y, **fit_args)\n",
      "  File \"/home/violeta/.local/lib/python3.8/site-packages/tensorflow/python/keras/engine/training.py\", line 1100, in fit\n",
      "    tmp_logs = self.train_function(iterator)\n",
      "  File \"/home/violeta/.local/lib/python3.8/site-packages/tensorflow/python/eager/def_function.py\", line 828, in __call__\n",
      "    result = self._call(*args, **kwds)\n",
      "  File \"/home/violeta/.local/lib/python3.8/site-packages/tensorflow/python/eager/def_function.py\", line 871, in _call\n",
      "    self._initialize(args, kwds, add_initializers_to=initializers)\n",
      "  File \"/home/violeta/.local/lib/python3.8/site-packages/tensorflow/python/eager/def_function.py\", line 725, in _initialize\n",
      "    self._stateful_fn._get_concrete_function_internal_garbage_collected(  # pylint: disable=protected-access\n",
      "  File \"/home/violeta/.local/lib/python3.8/site-packages/tensorflow/python/eager/function.py\", line 2969, in _get_concrete_function_internal_garbage_collected\n",
      "    graph_function, _ = self._maybe_define_function(args, kwargs)\n",
      "  File \"/home/violeta/.local/lib/python3.8/site-packages/tensorflow/python/eager/function.py\", line 3361, in _maybe_define_function\n",
      "    graph_function = self._create_graph_function(args, kwargs)\n",
      "  File \"/home/violeta/.local/lib/python3.8/site-packages/tensorflow/python/eager/function.py\", line 3196, in _create_graph_function\n",
      "    func_graph_module.func_graph_from_py_func(\n",
      "  File \"/home/violeta/.local/lib/python3.8/site-packages/tensorflow/python/framework/func_graph.py\", line 990, in func_graph_from_py_func\n",
      "    func_outputs = python_func(*func_args, **func_kwargs)\n",
      "  File \"/home/violeta/.local/lib/python3.8/site-packages/tensorflow/python/eager/def_function.py\", line 634, in wrapped_fn\n",
      "    out = weak_wrapped_fn().__wrapped__(*args, **kwds)\n",
      "  File \"/home/violeta/.local/lib/python3.8/site-packages/tensorflow/python/framework/func_graph.py\", line 977, in wrapper\n",
      "    raise e.ag_error_metadata.to_exception(e)\n",
      "ValueError: in user code:\n",
      "\n",
      "    /home/violeta/.local/lib/python3.8/site-packages/tensorflow/python/keras/engine/training.py:805 train_function  *\n",
      "        return step_function(self, iterator)\n",
      "    /home/violeta/.local/lib/python3.8/site-packages/tensorflow/python/keras/engine/training.py:795 step_function  **\n",
      "        outputs = model.distribute_strategy.run(run_step, args=(data,))\n",
      "    /home/violeta/.local/lib/python3.8/site-packages/tensorflow/python/distribute/distribute_lib.py:1259 run\n",
      "        return self._extended.call_for_each_replica(fn, args=args, kwargs=kwargs)\n",
      "    /home/violeta/.local/lib/python3.8/site-packages/tensorflow/python/distribute/distribute_lib.py:2730 call_for_each_replica\n",
      "        return self._call_for_each_replica(fn, args, kwargs)\n",
      "    /home/violeta/.local/lib/python3.8/site-packages/tensorflow/python/distribute/distribute_lib.py:3417 _call_for_each_replica\n",
      "        return fn(*args, **kwargs)\n",
      "    /home/violeta/.local/lib/python3.8/site-packages/tensorflow/python/keras/engine/training.py:788 run_step  **\n",
      "        outputs = model.train_step(data)\n",
      "    /home/violeta/.local/lib/python3.8/site-packages/tensorflow/python/keras/engine/training.py:754 train_step\n",
      "        y_pred = self(x, training=True)\n",
      "    /home/violeta/.local/lib/python3.8/site-packages/tensorflow/python/keras/engine/base_layer.py:998 __call__\n",
      "        input_spec.assert_input_compatibility(self.input_spec, inputs, self.name)\n",
      "    /home/violeta/.local/lib/python3.8/site-packages/tensorflow/python/keras/engine/input_spec.py:255 assert_input_compatibility\n",
      "        raise ValueError(\n",
      "\n",
      "    ValueError: Input 0 of layer sequential_19 is incompatible with the layer: expected axis -1 of input shape to have value 55 but received input with shape (5, 4281)\n",
      "\n",
      "\n",
      "  warnings.warn(\"Estimator fit failed. The score on this train-test\"\n"
     ]
    },
    {
     "name": "stderr",
     "output_type": "stream",
     "text": [
      "/home/violeta/.local/lib/python3.8/site-packages/sklearn/model_selection/_validation.py:610: FitFailedWarning: Estimator fit failed. The score on this train-test partition for these parameters will be set to nan. Details: \n",
      "Traceback (most recent call last):\n",
      "  File \"/home/violeta/.local/lib/python3.8/site-packages/sklearn/model_selection/_validation.py\", line 593, in _fit_and_score\n",
      "    estimator.fit(X_train, y_train, **fit_params)\n",
      "  File \"/home/violeta/.local/lib/python3.8/site-packages/tensorflow/python/keras/wrappers/scikit_learn.py\", line 223, in fit\n",
      "    return super(KerasClassifier, self).fit(x, y, **kwargs)\n",
      "  File \"/home/violeta/.local/lib/python3.8/site-packages/tensorflow/python/keras/wrappers/scikit_learn.py\", line 166, in fit\n",
      "    history = self.model.fit(x, y, **fit_args)\n",
      "  File \"/home/violeta/.local/lib/python3.8/site-packages/tensorflow/python/keras/engine/training.py\", line 1100, in fit\n",
      "    tmp_logs = self.train_function(iterator)\n",
      "  File \"/home/violeta/.local/lib/python3.8/site-packages/tensorflow/python/eager/def_function.py\", line 828, in __call__\n",
      "    result = self._call(*args, **kwds)\n",
      "  File \"/home/violeta/.local/lib/python3.8/site-packages/tensorflow/python/eager/def_function.py\", line 871, in _call\n",
      "    self._initialize(args, kwds, add_initializers_to=initializers)\n",
      "  File \"/home/violeta/.local/lib/python3.8/site-packages/tensorflow/python/eager/def_function.py\", line 725, in _initialize\n",
      "    self._stateful_fn._get_concrete_function_internal_garbage_collected(  # pylint: disable=protected-access\n",
      "  File \"/home/violeta/.local/lib/python3.8/site-packages/tensorflow/python/eager/function.py\", line 2969, in _get_concrete_function_internal_garbage_collected\n",
      "    graph_function, _ = self._maybe_define_function(args, kwargs)\n",
      "  File \"/home/violeta/.local/lib/python3.8/site-packages/tensorflow/python/eager/function.py\", line 3361, in _maybe_define_function\n",
      "    graph_function = self._create_graph_function(args, kwargs)\n",
      "  File \"/home/violeta/.local/lib/python3.8/site-packages/tensorflow/python/eager/function.py\", line 3196, in _create_graph_function\n",
      "    func_graph_module.func_graph_from_py_func(\n",
      "  File \"/home/violeta/.local/lib/python3.8/site-packages/tensorflow/python/framework/func_graph.py\", line 990, in func_graph_from_py_func\n",
      "    func_outputs = python_func(*func_args, **func_kwargs)\n",
      "  File \"/home/violeta/.local/lib/python3.8/site-packages/tensorflow/python/eager/def_function.py\", line 634, in wrapped_fn\n",
      "    out = weak_wrapped_fn().__wrapped__(*args, **kwds)\n",
      "  File \"/home/violeta/.local/lib/python3.8/site-packages/tensorflow/python/framework/func_graph.py\", line 977, in wrapper\n",
      "    raise e.ag_error_metadata.to_exception(e)\n",
      "ValueError: in user code:\n",
      "\n",
      "    /home/violeta/.local/lib/python3.8/site-packages/tensorflow/python/keras/engine/training.py:805 train_function  *\n",
      "        return step_function(self, iterator)\n",
      "    /home/violeta/.local/lib/python3.8/site-packages/tensorflow/python/keras/engine/training.py:795 step_function  **\n",
      "        outputs = model.distribute_strategy.run(run_step, args=(data,))\n",
      "    /home/violeta/.local/lib/python3.8/site-packages/tensorflow/python/distribute/distribute_lib.py:1259 run\n",
      "        return self._extended.call_for_each_replica(fn, args=args, kwargs=kwargs)\n",
      "    /home/violeta/.local/lib/python3.8/site-packages/tensorflow/python/distribute/distribute_lib.py:2730 call_for_each_replica\n",
      "        return self._call_for_each_replica(fn, args, kwargs)\n",
      "    /home/violeta/.local/lib/python3.8/site-packages/tensorflow/python/distribute/distribute_lib.py:3417 _call_for_each_replica\n",
      "        return fn(*args, **kwargs)\n",
      "    /home/violeta/.local/lib/python3.8/site-packages/tensorflow/python/keras/engine/training.py:788 run_step  **\n",
      "        outputs = model.train_step(data)\n",
      "    /home/violeta/.local/lib/python3.8/site-packages/tensorflow/python/keras/engine/training.py:754 train_step\n",
      "        y_pred = self(x, training=True)\n",
      "    /home/violeta/.local/lib/python3.8/site-packages/tensorflow/python/keras/engine/base_layer.py:998 __call__\n",
      "        input_spec.assert_input_compatibility(self.input_spec, inputs, self.name)\n",
      "    /home/violeta/.local/lib/python3.8/site-packages/tensorflow/python/keras/engine/input_spec.py:255 assert_input_compatibility\n",
      "        raise ValueError(\n",
      "\n",
      "    ValueError: Input 0 of layer sequential_20 is incompatible with the layer: expected axis -1 of input shape to have value 55 but received input with shape (None, 4281)\n",
      "\n",
      "\n",
      "  warnings.warn(\"Estimator fit failed. The score on this train-test\"\n",
      "/home/violeta/.local/lib/python3.8/site-packages/sklearn/model_selection/_validation.py:610: FitFailedWarning: Estimator fit failed. The score on this train-test partition for these parameters will be set to nan. Details: \n",
      "Traceback (most recent call last):\n",
      "  File \"/home/violeta/.local/lib/python3.8/site-packages/sklearn/model_selection/_validation.py\", line 593, in _fit_and_score\n",
      "    estimator.fit(X_train, y_train, **fit_params)\n",
      "  File \"/home/violeta/.local/lib/python3.8/site-packages/tensorflow/python/keras/wrappers/scikit_learn.py\", line 223, in fit\n",
      "    return super(KerasClassifier, self).fit(x, y, **kwargs)\n",
      "  File \"/home/violeta/.local/lib/python3.8/site-packages/tensorflow/python/keras/wrappers/scikit_learn.py\", line 166, in fit\n",
      "    history = self.model.fit(x, y, **fit_args)\n",
      "  File \"/home/violeta/.local/lib/python3.8/site-packages/tensorflow/python/keras/engine/training.py\", line 1100, in fit\n",
      "    tmp_logs = self.train_function(iterator)\n",
      "  File \"/home/violeta/.local/lib/python3.8/site-packages/tensorflow/python/eager/def_function.py\", line 828, in __call__\n",
      "    result = self._call(*args, **kwds)\n",
      "  File \"/home/violeta/.local/lib/python3.8/site-packages/tensorflow/python/eager/def_function.py\", line 871, in _call\n",
      "    self._initialize(args, kwds, add_initializers_to=initializers)\n",
      "  File \"/home/violeta/.local/lib/python3.8/site-packages/tensorflow/python/eager/def_function.py\", line 725, in _initialize\n",
      "    self._stateful_fn._get_concrete_function_internal_garbage_collected(  # pylint: disable=protected-access\n",
      "  File \"/home/violeta/.local/lib/python3.8/site-packages/tensorflow/python/eager/function.py\", line 2969, in _get_concrete_function_internal_garbage_collected\n",
      "    graph_function, _ = self._maybe_define_function(args, kwargs)\n",
      "  File \"/home/violeta/.local/lib/python3.8/site-packages/tensorflow/python/eager/function.py\", line 3361, in _maybe_define_function\n",
      "    graph_function = self._create_graph_function(args, kwargs)\n",
      "  File \"/home/violeta/.local/lib/python3.8/site-packages/tensorflow/python/eager/function.py\", line 3196, in _create_graph_function\n",
      "    func_graph_module.func_graph_from_py_func(\n",
      "  File \"/home/violeta/.local/lib/python3.8/site-packages/tensorflow/python/framework/func_graph.py\", line 990, in func_graph_from_py_func\n",
      "    func_outputs = python_func(*func_args, **func_kwargs)\n",
      "  File \"/home/violeta/.local/lib/python3.8/site-packages/tensorflow/python/eager/def_function.py\", line 634, in wrapped_fn\n",
      "    out = weak_wrapped_fn().__wrapped__(*args, **kwds)\n",
      "  File \"/home/violeta/.local/lib/python3.8/site-packages/tensorflow/python/framework/func_graph.py\", line 977, in wrapper\n",
      "    raise e.ag_error_metadata.to_exception(e)\n",
      "ValueError: in user code:\n",
      "\n",
      "    /home/violeta/.local/lib/python3.8/site-packages/tensorflow/python/keras/engine/training.py:805 train_function  *\n",
      "        return step_function(self, iterator)\n",
      "    /home/violeta/.local/lib/python3.8/site-packages/tensorflow/python/keras/engine/training.py:795 step_function  **\n",
      "        outputs = model.distribute_strategy.run(run_step, args=(data,))\n",
      "    /home/violeta/.local/lib/python3.8/site-packages/tensorflow/python/distribute/distribute_lib.py:1259 run\n",
      "        return self._extended.call_for_each_replica(fn, args=args, kwargs=kwargs)\n",
      "    /home/violeta/.local/lib/python3.8/site-packages/tensorflow/python/distribute/distribute_lib.py:2730 call_for_each_replica\n",
      "        return self._call_for_each_replica(fn, args, kwargs)\n",
      "    /home/violeta/.local/lib/python3.8/site-packages/tensorflow/python/distribute/distribute_lib.py:3417 _call_for_each_replica\n",
      "        return fn(*args, **kwargs)\n",
      "    /home/violeta/.local/lib/python3.8/site-packages/tensorflow/python/keras/engine/training.py:788 run_step  **\n",
      "        outputs = model.train_step(data)\n",
      "    /home/violeta/.local/lib/python3.8/site-packages/tensorflow/python/keras/engine/training.py:754 train_step\n",
      "        y_pred = self(x, training=True)\n",
      "    /home/violeta/.local/lib/python3.8/site-packages/tensorflow/python/keras/engine/base_layer.py:998 __call__\n",
      "        input_spec.assert_input_compatibility(self.input_spec, inputs, self.name)\n",
      "    /home/violeta/.local/lib/python3.8/site-packages/tensorflow/python/keras/engine/input_spec.py:255 assert_input_compatibility\n",
      "        raise ValueError(\n",
      "\n",
      "    ValueError: Input 0 of layer sequential_21 is incompatible with the layer: expected axis -1 of input shape to have value 55 but received input with shape (None, 4281)\n",
      "\n",
      "\n",
      "  warnings.warn(\"Estimator fit failed. The score on this train-test\"\n"
     ]
    },
    {
     "name": "stderr",
     "output_type": "stream",
     "text": [
      "/home/violeta/.local/lib/python3.8/site-packages/sklearn/model_selection/_validation.py:610: FitFailedWarning: Estimator fit failed. The score on this train-test partition for these parameters will be set to nan. Details: \n",
      "Traceback (most recent call last):\n",
      "  File \"/home/violeta/.local/lib/python3.8/site-packages/sklearn/model_selection/_validation.py\", line 593, in _fit_and_score\n",
      "    estimator.fit(X_train, y_train, **fit_params)\n",
      "  File \"/home/violeta/.local/lib/python3.8/site-packages/tensorflow/python/keras/wrappers/scikit_learn.py\", line 223, in fit\n",
      "    return super(KerasClassifier, self).fit(x, y, **kwargs)\n",
      "  File \"/home/violeta/.local/lib/python3.8/site-packages/tensorflow/python/keras/wrappers/scikit_learn.py\", line 166, in fit\n",
      "    history = self.model.fit(x, y, **fit_args)\n",
      "  File \"/home/violeta/.local/lib/python3.8/site-packages/tensorflow/python/keras/engine/training.py\", line 1100, in fit\n",
      "    tmp_logs = self.train_function(iterator)\n",
      "  File \"/home/violeta/.local/lib/python3.8/site-packages/tensorflow/python/eager/def_function.py\", line 828, in __call__\n",
      "    result = self._call(*args, **kwds)\n",
      "  File \"/home/violeta/.local/lib/python3.8/site-packages/tensorflow/python/eager/def_function.py\", line 871, in _call\n",
      "    self._initialize(args, kwds, add_initializers_to=initializers)\n",
      "  File \"/home/violeta/.local/lib/python3.8/site-packages/tensorflow/python/eager/def_function.py\", line 725, in _initialize\n",
      "    self._stateful_fn._get_concrete_function_internal_garbage_collected(  # pylint: disable=protected-access\n",
      "  File \"/home/violeta/.local/lib/python3.8/site-packages/tensorflow/python/eager/function.py\", line 2969, in _get_concrete_function_internal_garbage_collected\n",
      "    graph_function, _ = self._maybe_define_function(args, kwargs)\n",
      "  File \"/home/violeta/.local/lib/python3.8/site-packages/tensorflow/python/eager/function.py\", line 3361, in _maybe_define_function\n",
      "    graph_function = self._create_graph_function(args, kwargs)\n",
      "  File \"/home/violeta/.local/lib/python3.8/site-packages/tensorflow/python/eager/function.py\", line 3196, in _create_graph_function\n",
      "    func_graph_module.func_graph_from_py_func(\n",
      "  File \"/home/violeta/.local/lib/python3.8/site-packages/tensorflow/python/framework/func_graph.py\", line 990, in func_graph_from_py_func\n",
      "    func_outputs = python_func(*func_args, **func_kwargs)\n",
      "  File \"/home/violeta/.local/lib/python3.8/site-packages/tensorflow/python/eager/def_function.py\", line 634, in wrapped_fn\n",
      "    out = weak_wrapped_fn().__wrapped__(*args, **kwds)\n",
      "  File \"/home/violeta/.local/lib/python3.8/site-packages/tensorflow/python/framework/func_graph.py\", line 977, in wrapper\n",
      "    raise e.ag_error_metadata.to_exception(e)\n",
      "ValueError: in user code:\n",
      "\n",
      "    /home/violeta/.local/lib/python3.8/site-packages/tensorflow/python/keras/engine/training.py:805 train_function  *\n",
      "        return step_function(self, iterator)\n",
      "    /home/violeta/.local/lib/python3.8/site-packages/tensorflow/python/keras/engine/training.py:795 step_function  **\n",
      "        outputs = model.distribute_strategy.run(run_step, args=(data,))\n",
      "    /home/violeta/.local/lib/python3.8/site-packages/tensorflow/python/distribute/distribute_lib.py:1259 run\n",
      "        return self._extended.call_for_each_replica(fn, args=args, kwargs=kwargs)\n",
      "    /home/violeta/.local/lib/python3.8/site-packages/tensorflow/python/distribute/distribute_lib.py:2730 call_for_each_replica\n",
      "        return self._call_for_each_replica(fn, args, kwargs)\n",
      "    /home/violeta/.local/lib/python3.8/site-packages/tensorflow/python/distribute/distribute_lib.py:3417 _call_for_each_replica\n",
      "        return fn(*args, **kwargs)\n",
      "    /home/violeta/.local/lib/python3.8/site-packages/tensorflow/python/keras/engine/training.py:788 run_step  **\n",
      "        outputs = model.train_step(data)\n",
      "    /home/violeta/.local/lib/python3.8/site-packages/tensorflow/python/keras/engine/training.py:754 train_step\n",
      "        y_pred = self(x, training=True)\n",
      "    /home/violeta/.local/lib/python3.8/site-packages/tensorflow/python/keras/engine/base_layer.py:998 __call__\n",
      "        input_spec.assert_input_compatibility(self.input_spec, inputs, self.name)\n",
      "    /home/violeta/.local/lib/python3.8/site-packages/tensorflow/python/keras/engine/input_spec.py:255 assert_input_compatibility\n",
      "        raise ValueError(\n",
      "\n",
      "    ValueError: Input 0 of layer sequential_22 is incompatible with the layer: expected axis -1 of input shape to have value 55 but received input with shape (None, 4281)\n",
      "\n",
      "\n",
      "  warnings.warn(\"Estimator fit failed. The score on this train-test\"\n",
      "/home/violeta/.local/lib/python3.8/site-packages/sklearn/model_selection/_validation.py:610: FitFailedWarning: Estimator fit failed. The score on this train-test partition for these parameters will be set to nan. Details: \n",
      "Traceback (most recent call last):\n",
      "  File \"/home/violeta/.local/lib/python3.8/site-packages/sklearn/model_selection/_validation.py\", line 593, in _fit_and_score\n",
      "    estimator.fit(X_train, y_train, **fit_params)\n",
      "  File \"/home/violeta/.local/lib/python3.8/site-packages/tensorflow/python/keras/wrappers/scikit_learn.py\", line 223, in fit\n",
      "    return super(KerasClassifier, self).fit(x, y, **kwargs)\n",
      "  File \"/home/violeta/.local/lib/python3.8/site-packages/tensorflow/python/keras/wrappers/scikit_learn.py\", line 166, in fit\n",
      "    history = self.model.fit(x, y, **fit_args)\n",
      "  File \"/home/violeta/.local/lib/python3.8/site-packages/tensorflow/python/keras/engine/training.py\", line 1100, in fit\n",
      "    tmp_logs = self.train_function(iterator)\n",
      "  File \"/home/violeta/.local/lib/python3.8/site-packages/tensorflow/python/eager/def_function.py\", line 828, in __call__\n",
      "    result = self._call(*args, **kwds)\n",
      "  File \"/home/violeta/.local/lib/python3.8/site-packages/tensorflow/python/eager/def_function.py\", line 871, in _call\n",
      "    self._initialize(args, kwds, add_initializers_to=initializers)\n",
      "  File \"/home/violeta/.local/lib/python3.8/site-packages/tensorflow/python/eager/def_function.py\", line 725, in _initialize\n",
      "    self._stateful_fn._get_concrete_function_internal_garbage_collected(  # pylint: disable=protected-access\n",
      "  File \"/home/violeta/.local/lib/python3.8/site-packages/tensorflow/python/eager/function.py\", line 2969, in _get_concrete_function_internal_garbage_collected\n",
      "    graph_function, _ = self._maybe_define_function(args, kwargs)\n",
      "  File \"/home/violeta/.local/lib/python3.8/site-packages/tensorflow/python/eager/function.py\", line 3361, in _maybe_define_function\n",
      "    graph_function = self._create_graph_function(args, kwargs)\n",
      "  File \"/home/violeta/.local/lib/python3.8/site-packages/tensorflow/python/eager/function.py\", line 3196, in _create_graph_function\n",
      "    func_graph_module.func_graph_from_py_func(\n",
      "  File \"/home/violeta/.local/lib/python3.8/site-packages/tensorflow/python/framework/func_graph.py\", line 990, in func_graph_from_py_func\n",
      "    func_outputs = python_func(*func_args, **func_kwargs)\n",
      "  File \"/home/violeta/.local/lib/python3.8/site-packages/tensorflow/python/eager/def_function.py\", line 634, in wrapped_fn\n",
      "    out = weak_wrapped_fn().__wrapped__(*args, **kwds)\n",
      "  File \"/home/violeta/.local/lib/python3.8/site-packages/tensorflow/python/framework/func_graph.py\", line 977, in wrapper\n",
      "    raise e.ag_error_metadata.to_exception(e)\n",
      "ValueError: in user code:\n",
      "\n",
      "    /home/violeta/.local/lib/python3.8/site-packages/tensorflow/python/keras/engine/training.py:805 train_function  *\n",
      "        return step_function(self, iterator)\n",
      "    /home/violeta/.local/lib/python3.8/site-packages/tensorflow/python/keras/engine/training.py:795 step_function  **\n",
      "        outputs = model.distribute_strategy.run(run_step, args=(data,))\n",
      "    /home/violeta/.local/lib/python3.8/site-packages/tensorflow/python/distribute/distribute_lib.py:1259 run\n",
      "        return self._extended.call_for_each_replica(fn, args=args, kwargs=kwargs)\n",
      "    /home/violeta/.local/lib/python3.8/site-packages/tensorflow/python/distribute/distribute_lib.py:2730 call_for_each_replica\n",
      "        return self._call_for_each_replica(fn, args, kwargs)\n",
      "    /home/violeta/.local/lib/python3.8/site-packages/tensorflow/python/distribute/distribute_lib.py:3417 _call_for_each_replica\n",
      "        return fn(*args, **kwargs)\n",
      "    /home/violeta/.local/lib/python3.8/site-packages/tensorflow/python/keras/engine/training.py:788 run_step  **\n",
      "        outputs = model.train_step(data)\n",
      "    /home/violeta/.local/lib/python3.8/site-packages/tensorflow/python/keras/engine/training.py:754 train_step\n",
      "        y_pred = self(x, training=True)\n",
      "    /home/violeta/.local/lib/python3.8/site-packages/tensorflow/python/keras/engine/base_layer.py:998 __call__\n",
      "        input_spec.assert_input_compatibility(self.input_spec, inputs, self.name)\n",
      "    /home/violeta/.local/lib/python3.8/site-packages/tensorflow/python/keras/engine/input_spec.py:255 assert_input_compatibility\n",
      "        raise ValueError(\n",
      "\n",
      "    ValueError: Input 0 of layer sequential_23 is incompatible with the layer: expected axis -1 of input shape to have value 55 but received input with shape (5, 4281)\n",
      "\n",
      "\n",
      "  warnings.warn(\"Estimator fit failed. The score on this train-test\"\n"
     ]
    },
    {
     "name": "stderr",
     "output_type": "stream",
     "text": [
      "/home/violeta/.local/lib/python3.8/site-packages/sklearn/model_selection/_validation.py:610: FitFailedWarning: Estimator fit failed. The score on this train-test partition for these parameters will be set to nan. Details: \n",
      "Traceback (most recent call last):\n",
      "  File \"/home/violeta/.local/lib/python3.8/site-packages/sklearn/model_selection/_validation.py\", line 593, in _fit_and_score\n",
      "    estimator.fit(X_train, y_train, **fit_params)\n",
      "  File \"/home/violeta/.local/lib/python3.8/site-packages/tensorflow/python/keras/wrappers/scikit_learn.py\", line 223, in fit\n",
      "    return super(KerasClassifier, self).fit(x, y, **kwargs)\n",
      "  File \"/home/violeta/.local/lib/python3.8/site-packages/tensorflow/python/keras/wrappers/scikit_learn.py\", line 166, in fit\n",
      "    history = self.model.fit(x, y, **fit_args)\n",
      "  File \"/home/violeta/.local/lib/python3.8/site-packages/tensorflow/python/keras/engine/training.py\", line 1100, in fit\n",
      "    tmp_logs = self.train_function(iterator)\n",
      "  File \"/home/violeta/.local/lib/python3.8/site-packages/tensorflow/python/eager/def_function.py\", line 828, in __call__\n",
      "    result = self._call(*args, **kwds)\n",
      "  File \"/home/violeta/.local/lib/python3.8/site-packages/tensorflow/python/eager/def_function.py\", line 871, in _call\n",
      "    self._initialize(args, kwds, add_initializers_to=initializers)\n",
      "  File \"/home/violeta/.local/lib/python3.8/site-packages/tensorflow/python/eager/def_function.py\", line 725, in _initialize\n",
      "    self._stateful_fn._get_concrete_function_internal_garbage_collected(  # pylint: disable=protected-access\n",
      "  File \"/home/violeta/.local/lib/python3.8/site-packages/tensorflow/python/eager/function.py\", line 2969, in _get_concrete_function_internal_garbage_collected\n",
      "    graph_function, _ = self._maybe_define_function(args, kwargs)\n",
      "  File \"/home/violeta/.local/lib/python3.8/site-packages/tensorflow/python/eager/function.py\", line 3361, in _maybe_define_function\n",
      "    graph_function = self._create_graph_function(args, kwargs)\n",
      "  File \"/home/violeta/.local/lib/python3.8/site-packages/tensorflow/python/eager/function.py\", line 3196, in _create_graph_function\n",
      "    func_graph_module.func_graph_from_py_func(\n",
      "  File \"/home/violeta/.local/lib/python3.8/site-packages/tensorflow/python/framework/func_graph.py\", line 990, in func_graph_from_py_func\n",
      "    func_outputs = python_func(*func_args, **func_kwargs)\n",
      "  File \"/home/violeta/.local/lib/python3.8/site-packages/tensorflow/python/eager/def_function.py\", line 634, in wrapped_fn\n",
      "    out = weak_wrapped_fn().__wrapped__(*args, **kwds)\n",
      "  File \"/home/violeta/.local/lib/python3.8/site-packages/tensorflow/python/framework/func_graph.py\", line 977, in wrapper\n",
      "    raise e.ag_error_metadata.to_exception(e)\n",
      "ValueError: in user code:\n",
      "\n",
      "    /home/violeta/.local/lib/python3.8/site-packages/tensorflow/python/keras/engine/training.py:805 train_function  *\n",
      "        return step_function(self, iterator)\n",
      "    /home/violeta/.local/lib/python3.8/site-packages/tensorflow/python/keras/engine/training.py:795 step_function  **\n",
      "        outputs = model.distribute_strategy.run(run_step, args=(data,))\n",
      "    /home/violeta/.local/lib/python3.8/site-packages/tensorflow/python/distribute/distribute_lib.py:1259 run\n",
      "        return self._extended.call_for_each_replica(fn, args=args, kwargs=kwargs)\n",
      "    /home/violeta/.local/lib/python3.8/site-packages/tensorflow/python/distribute/distribute_lib.py:2730 call_for_each_replica\n",
      "        return self._call_for_each_replica(fn, args, kwargs)\n",
      "    /home/violeta/.local/lib/python3.8/site-packages/tensorflow/python/distribute/distribute_lib.py:3417 _call_for_each_replica\n",
      "        return fn(*args, **kwargs)\n",
      "    /home/violeta/.local/lib/python3.8/site-packages/tensorflow/python/keras/engine/training.py:788 run_step  **\n",
      "        outputs = model.train_step(data)\n",
      "    /home/violeta/.local/lib/python3.8/site-packages/tensorflow/python/keras/engine/training.py:754 train_step\n",
      "        y_pred = self(x, training=True)\n",
      "    /home/violeta/.local/lib/python3.8/site-packages/tensorflow/python/keras/engine/base_layer.py:998 __call__\n",
      "        input_spec.assert_input_compatibility(self.input_spec, inputs, self.name)\n",
      "    /home/violeta/.local/lib/python3.8/site-packages/tensorflow/python/keras/engine/input_spec.py:255 assert_input_compatibility\n",
      "        raise ValueError(\n",
      "\n",
      "    ValueError: Input 0 of layer sequential_24 is incompatible with the layer: expected axis -1 of input shape to have value 55 but received input with shape (5, 4281)\n",
      "\n",
      "\n",
      "  warnings.warn(\"Estimator fit failed. The score on this train-test\"\n",
      "/home/violeta/.local/lib/python3.8/site-packages/sklearn/model_selection/_validation.py:610: FitFailedWarning: Estimator fit failed. The score on this train-test partition for these parameters will be set to nan. Details: \n",
      "Traceback (most recent call last):\n",
      "  File \"/home/violeta/.local/lib/python3.8/site-packages/sklearn/model_selection/_validation.py\", line 593, in _fit_and_score\n",
      "    estimator.fit(X_train, y_train, **fit_params)\n",
      "  File \"/home/violeta/.local/lib/python3.8/site-packages/tensorflow/python/keras/wrappers/scikit_learn.py\", line 223, in fit\n",
      "    return super(KerasClassifier, self).fit(x, y, **kwargs)\n",
      "  File \"/home/violeta/.local/lib/python3.8/site-packages/tensorflow/python/keras/wrappers/scikit_learn.py\", line 166, in fit\n",
      "    history = self.model.fit(x, y, **fit_args)\n",
      "  File \"/home/violeta/.local/lib/python3.8/site-packages/tensorflow/python/keras/engine/training.py\", line 1100, in fit\n",
      "    tmp_logs = self.train_function(iterator)\n",
      "  File \"/home/violeta/.local/lib/python3.8/site-packages/tensorflow/python/eager/def_function.py\", line 828, in __call__\n",
      "    result = self._call(*args, **kwds)\n",
      "  File \"/home/violeta/.local/lib/python3.8/site-packages/tensorflow/python/eager/def_function.py\", line 871, in _call\n",
      "    self._initialize(args, kwds, add_initializers_to=initializers)\n",
      "  File \"/home/violeta/.local/lib/python3.8/site-packages/tensorflow/python/eager/def_function.py\", line 725, in _initialize\n",
      "    self._stateful_fn._get_concrete_function_internal_garbage_collected(  # pylint: disable=protected-access\n",
      "  File \"/home/violeta/.local/lib/python3.8/site-packages/tensorflow/python/eager/function.py\", line 2969, in _get_concrete_function_internal_garbage_collected\n",
      "    graph_function, _ = self._maybe_define_function(args, kwargs)\n",
      "  File \"/home/violeta/.local/lib/python3.8/site-packages/tensorflow/python/eager/function.py\", line 3361, in _maybe_define_function\n",
      "    graph_function = self._create_graph_function(args, kwargs)\n",
      "  File \"/home/violeta/.local/lib/python3.8/site-packages/tensorflow/python/eager/function.py\", line 3196, in _create_graph_function\n",
      "    func_graph_module.func_graph_from_py_func(\n",
      "  File \"/home/violeta/.local/lib/python3.8/site-packages/tensorflow/python/framework/func_graph.py\", line 990, in func_graph_from_py_func\n",
      "    func_outputs = python_func(*func_args, **func_kwargs)\n",
      "  File \"/home/violeta/.local/lib/python3.8/site-packages/tensorflow/python/eager/def_function.py\", line 634, in wrapped_fn\n",
      "    out = weak_wrapped_fn().__wrapped__(*args, **kwds)\n",
      "  File \"/home/violeta/.local/lib/python3.8/site-packages/tensorflow/python/framework/func_graph.py\", line 977, in wrapper\n",
      "    raise e.ag_error_metadata.to_exception(e)\n",
      "ValueError: in user code:\n",
      "\n",
      "    /home/violeta/.local/lib/python3.8/site-packages/tensorflow/python/keras/engine/training.py:805 train_function  *\n",
      "        return step_function(self, iterator)\n",
      "    /home/violeta/.local/lib/python3.8/site-packages/tensorflow/python/keras/engine/training.py:795 step_function  **\n",
      "        outputs = model.distribute_strategy.run(run_step, args=(data,))\n",
      "    /home/violeta/.local/lib/python3.8/site-packages/tensorflow/python/distribute/distribute_lib.py:1259 run\n",
      "        return self._extended.call_for_each_replica(fn, args=args, kwargs=kwargs)\n",
      "    /home/violeta/.local/lib/python3.8/site-packages/tensorflow/python/distribute/distribute_lib.py:2730 call_for_each_replica\n",
      "        return self._call_for_each_replica(fn, args, kwargs)\n",
      "    /home/violeta/.local/lib/python3.8/site-packages/tensorflow/python/distribute/distribute_lib.py:3417 _call_for_each_replica\n",
      "        return fn(*args, **kwargs)\n",
      "    /home/violeta/.local/lib/python3.8/site-packages/tensorflow/python/keras/engine/training.py:788 run_step  **\n",
      "        outputs = model.train_step(data)\n",
      "    /home/violeta/.local/lib/python3.8/site-packages/tensorflow/python/keras/engine/training.py:754 train_step\n",
      "        y_pred = self(x, training=True)\n",
      "    /home/violeta/.local/lib/python3.8/site-packages/tensorflow/python/keras/engine/base_layer.py:998 __call__\n",
      "        input_spec.assert_input_compatibility(self.input_spec, inputs, self.name)\n",
      "    /home/violeta/.local/lib/python3.8/site-packages/tensorflow/python/keras/engine/input_spec.py:255 assert_input_compatibility\n",
      "        raise ValueError(\n",
      "\n",
      "    ValueError: Input 0 of layer sequential_25 is incompatible with the layer: expected axis -1 of input shape to have value 55 but received input with shape (None, 4281)\n",
      "\n",
      "\n",
      "  warnings.warn(\"Estimator fit failed. The score on this train-test\"\n"
     ]
    },
    {
     "name": "stderr",
     "output_type": "stream",
     "text": [
      "/home/violeta/.local/lib/python3.8/site-packages/sklearn/model_selection/_validation.py:610: FitFailedWarning: Estimator fit failed. The score on this train-test partition for these parameters will be set to nan. Details: \n",
      "Traceback (most recent call last):\n",
      "  File \"/home/violeta/.local/lib/python3.8/site-packages/sklearn/model_selection/_validation.py\", line 593, in _fit_and_score\n",
      "    estimator.fit(X_train, y_train, **fit_params)\n",
      "  File \"/home/violeta/.local/lib/python3.8/site-packages/tensorflow/python/keras/wrappers/scikit_learn.py\", line 223, in fit\n",
      "    return super(KerasClassifier, self).fit(x, y, **kwargs)\n",
      "  File \"/home/violeta/.local/lib/python3.8/site-packages/tensorflow/python/keras/wrappers/scikit_learn.py\", line 166, in fit\n",
      "    history = self.model.fit(x, y, **fit_args)\n",
      "  File \"/home/violeta/.local/lib/python3.8/site-packages/tensorflow/python/keras/engine/training.py\", line 1100, in fit\n",
      "    tmp_logs = self.train_function(iterator)\n",
      "  File \"/home/violeta/.local/lib/python3.8/site-packages/tensorflow/python/eager/def_function.py\", line 828, in __call__\n",
      "    result = self._call(*args, **kwds)\n",
      "  File \"/home/violeta/.local/lib/python3.8/site-packages/tensorflow/python/eager/def_function.py\", line 871, in _call\n",
      "    self._initialize(args, kwds, add_initializers_to=initializers)\n",
      "  File \"/home/violeta/.local/lib/python3.8/site-packages/tensorflow/python/eager/def_function.py\", line 725, in _initialize\n",
      "    self._stateful_fn._get_concrete_function_internal_garbage_collected(  # pylint: disable=protected-access\n",
      "  File \"/home/violeta/.local/lib/python3.8/site-packages/tensorflow/python/eager/function.py\", line 2969, in _get_concrete_function_internal_garbage_collected\n",
      "    graph_function, _ = self._maybe_define_function(args, kwargs)\n",
      "  File \"/home/violeta/.local/lib/python3.8/site-packages/tensorflow/python/eager/function.py\", line 3361, in _maybe_define_function\n",
      "    graph_function = self._create_graph_function(args, kwargs)\n",
      "  File \"/home/violeta/.local/lib/python3.8/site-packages/tensorflow/python/eager/function.py\", line 3196, in _create_graph_function\n",
      "    func_graph_module.func_graph_from_py_func(\n",
      "  File \"/home/violeta/.local/lib/python3.8/site-packages/tensorflow/python/framework/func_graph.py\", line 990, in func_graph_from_py_func\n",
      "    func_outputs = python_func(*func_args, **func_kwargs)\n",
      "  File \"/home/violeta/.local/lib/python3.8/site-packages/tensorflow/python/eager/def_function.py\", line 634, in wrapped_fn\n",
      "    out = weak_wrapped_fn().__wrapped__(*args, **kwds)\n",
      "  File \"/home/violeta/.local/lib/python3.8/site-packages/tensorflow/python/framework/func_graph.py\", line 977, in wrapper\n",
      "    raise e.ag_error_metadata.to_exception(e)\n",
      "ValueError: in user code:\n",
      "\n",
      "    /home/violeta/.local/lib/python3.8/site-packages/tensorflow/python/keras/engine/training.py:805 train_function  *\n",
      "        return step_function(self, iterator)\n",
      "    /home/violeta/.local/lib/python3.8/site-packages/tensorflow/python/keras/engine/training.py:795 step_function  **\n",
      "        outputs = model.distribute_strategy.run(run_step, args=(data,))\n",
      "    /home/violeta/.local/lib/python3.8/site-packages/tensorflow/python/distribute/distribute_lib.py:1259 run\n",
      "        return self._extended.call_for_each_replica(fn, args=args, kwargs=kwargs)\n",
      "    /home/violeta/.local/lib/python3.8/site-packages/tensorflow/python/distribute/distribute_lib.py:2730 call_for_each_replica\n",
      "        return self._call_for_each_replica(fn, args, kwargs)\n",
      "    /home/violeta/.local/lib/python3.8/site-packages/tensorflow/python/distribute/distribute_lib.py:3417 _call_for_each_replica\n",
      "        return fn(*args, **kwargs)\n",
      "    /home/violeta/.local/lib/python3.8/site-packages/tensorflow/python/keras/engine/training.py:788 run_step  **\n",
      "        outputs = model.train_step(data)\n",
      "    /home/violeta/.local/lib/python3.8/site-packages/tensorflow/python/keras/engine/training.py:754 train_step\n",
      "        y_pred = self(x, training=True)\n",
      "    /home/violeta/.local/lib/python3.8/site-packages/tensorflow/python/keras/engine/base_layer.py:998 __call__\n",
      "        input_spec.assert_input_compatibility(self.input_spec, inputs, self.name)\n",
      "    /home/violeta/.local/lib/python3.8/site-packages/tensorflow/python/keras/engine/input_spec.py:255 assert_input_compatibility\n",
      "        raise ValueError(\n",
      "\n",
      "    ValueError: Input 0 of layer sequential_26 is incompatible with the layer: expected axis -1 of input shape to have value 55 but received input with shape (None, 4281)\n",
      "\n",
      "\n",
      "  warnings.warn(\"Estimator fit failed. The score on this train-test\"\n",
      "/home/violeta/.local/lib/python3.8/site-packages/sklearn/model_selection/_validation.py:610: FitFailedWarning: Estimator fit failed. The score on this train-test partition for these parameters will be set to nan. Details: \n",
      "Traceback (most recent call last):\n",
      "  File \"/home/violeta/.local/lib/python3.8/site-packages/sklearn/model_selection/_validation.py\", line 593, in _fit_and_score\n",
      "    estimator.fit(X_train, y_train, **fit_params)\n",
      "  File \"/home/violeta/.local/lib/python3.8/site-packages/tensorflow/python/keras/wrappers/scikit_learn.py\", line 223, in fit\n",
      "    return super(KerasClassifier, self).fit(x, y, **kwargs)\n",
      "  File \"/home/violeta/.local/lib/python3.8/site-packages/tensorflow/python/keras/wrappers/scikit_learn.py\", line 166, in fit\n",
      "    history = self.model.fit(x, y, **fit_args)\n",
      "  File \"/home/violeta/.local/lib/python3.8/site-packages/tensorflow/python/keras/engine/training.py\", line 1100, in fit\n",
      "    tmp_logs = self.train_function(iterator)\n",
      "  File \"/home/violeta/.local/lib/python3.8/site-packages/tensorflow/python/eager/def_function.py\", line 828, in __call__\n",
      "    result = self._call(*args, **kwds)\n",
      "  File \"/home/violeta/.local/lib/python3.8/site-packages/tensorflow/python/eager/def_function.py\", line 871, in _call\n",
      "    self._initialize(args, kwds, add_initializers_to=initializers)\n",
      "  File \"/home/violeta/.local/lib/python3.8/site-packages/tensorflow/python/eager/def_function.py\", line 725, in _initialize\n",
      "    self._stateful_fn._get_concrete_function_internal_garbage_collected(  # pylint: disable=protected-access\n",
      "  File \"/home/violeta/.local/lib/python3.8/site-packages/tensorflow/python/eager/function.py\", line 2969, in _get_concrete_function_internal_garbage_collected\n",
      "    graph_function, _ = self._maybe_define_function(args, kwargs)\n",
      "  File \"/home/violeta/.local/lib/python3.8/site-packages/tensorflow/python/eager/function.py\", line 3361, in _maybe_define_function\n",
      "    graph_function = self._create_graph_function(args, kwargs)\n",
      "  File \"/home/violeta/.local/lib/python3.8/site-packages/tensorflow/python/eager/function.py\", line 3196, in _create_graph_function\n",
      "    func_graph_module.func_graph_from_py_func(\n",
      "  File \"/home/violeta/.local/lib/python3.8/site-packages/tensorflow/python/framework/func_graph.py\", line 990, in func_graph_from_py_func\n",
      "    func_outputs = python_func(*func_args, **func_kwargs)\n",
      "  File \"/home/violeta/.local/lib/python3.8/site-packages/tensorflow/python/eager/def_function.py\", line 634, in wrapped_fn\n",
      "    out = weak_wrapped_fn().__wrapped__(*args, **kwds)\n",
      "  File \"/home/violeta/.local/lib/python3.8/site-packages/tensorflow/python/framework/func_graph.py\", line 977, in wrapper\n",
      "    raise e.ag_error_metadata.to_exception(e)\n",
      "ValueError: in user code:\n",
      "\n",
      "    /home/violeta/.local/lib/python3.8/site-packages/tensorflow/python/keras/engine/training.py:805 train_function  *\n",
      "        return step_function(self, iterator)\n",
      "    /home/violeta/.local/lib/python3.8/site-packages/tensorflow/python/keras/engine/training.py:795 step_function  **\n",
      "        outputs = model.distribute_strategy.run(run_step, args=(data,))\n",
      "    /home/violeta/.local/lib/python3.8/site-packages/tensorflow/python/distribute/distribute_lib.py:1259 run\n",
      "        return self._extended.call_for_each_replica(fn, args=args, kwargs=kwargs)\n",
      "    /home/violeta/.local/lib/python3.8/site-packages/tensorflow/python/distribute/distribute_lib.py:2730 call_for_each_replica\n",
      "        return self._call_for_each_replica(fn, args, kwargs)\n",
      "    /home/violeta/.local/lib/python3.8/site-packages/tensorflow/python/distribute/distribute_lib.py:3417 _call_for_each_replica\n",
      "        return fn(*args, **kwargs)\n",
      "    /home/violeta/.local/lib/python3.8/site-packages/tensorflow/python/keras/engine/training.py:788 run_step  **\n",
      "        outputs = model.train_step(data)\n",
      "    /home/violeta/.local/lib/python3.8/site-packages/tensorflow/python/keras/engine/training.py:754 train_step\n",
      "        y_pred = self(x, training=True)\n",
      "    /home/violeta/.local/lib/python3.8/site-packages/tensorflow/python/keras/engine/base_layer.py:998 __call__\n",
      "        input_spec.assert_input_compatibility(self.input_spec, inputs, self.name)\n",
      "    /home/violeta/.local/lib/python3.8/site-packages/tensorflow/python/keras/engine/input_spec.py:255 assert_input_compatibility\n",
      "        raise ValueError(\n",
      "\n",
      "    ValueError: Input 0 of layer sequential_27 is incompatible with the layer: expected axis -1 of input shape to have value 55 but received input with shape (None, 4281)\n",
      "\n",
      "\n",
      "  warnings.warn(\"Estimator fit failed. The score on this train-test\"\n"
     ]
    },
    {
     "name": "stderr",
     "output_type": "stream",
     "text": [
      "/home/violeta/.local/lib/python3.8/site-packages/sklearn/model_selection/_validation.py:610: FitFailedWarning: Estimator fit failed. The score on this train-test partition for these parameters will be set to nan. Details: \n",
      "Traceback (most recent call last):\n",
      "  File \"/home/violeta/.local/lib/python3.8/site-packages/sklearn/model_selection/_validation.py\", line 593, in _fit_and_score\n",
      "    estimator.fit(X_train, y_train, **fit_params)\n",
      "  File \"/home/violeta/.local/lib/python3.8/site-packages/tensorflow/python/keras/wrappers/scikit_learn.py\", line 223, in fit\n",
      "    return super(KerasClassifier, self).fit(x, y, **kwargs)\n",
      "  File \"/home/violeta/.local/lib/python3.8/site-packages/tensorflow/python/keras/wrappers/scikit_learn.py\", line 166, in fit\n",
      "    history = self.model.fit(x, y, **fit_args)\n",
      "  File \"/home/violeta/.local/lib/python3.8/site-packages/tensorflow/python/keras/engine/training.py\", line 1100, in fit\n",
      "    tmp_logs = self.train_function(iterator)\n",
      "  File \"/home/violeta/.local/lib/python3.8/site-packages/tensorflow/python/eager/def_function.py\", line 828, in __call__\n",
      "    result = self._call(*args, **kwds)\n",
      "  File \"/home/violeta/.local/lib/python3.8/site-packages/tensorflow/python/eager/def_function.py\", line 871, in _call\n",
      "    self._initialize(args, kwds, add_initializers_to=initializers)\n",
      "  File \"/home/violeta/.local/lib/python3.8/site-packages/tensorflow/python/eager/def_function.py\", line 725, in _initialize\n",
      "    self._stateful_fn._get_concrete_function_internal_garbage_collected(  # pylint: disable=protected-access\n",
      "  File \"/home/violeta/.local/lib/python3.8/site-packages/tensorflow/python/eager/function.py\", line 2969, in _get_concrete_function_internal_garbage_collected\n",
      "    graph_function, _ = self._maybe_define_function(args, kwargs)\n",
      "  File \"/home/violeta/.local/lib/python3.8/site-packages/tensorflow/python/eager/function.py\", line 3361, in _maybe_define_function\n",
      "    graph_function = self._create_graph_function(args, kwargs)\n",
      "  File \"/home/violeta/.local/lib/python3.8/site-packages/tensorflow/python/eager/function.py\", line 3196, in _create_graph_function\n",
      "    func_graph_module.func_graph_from_py_func(\n",
      "  File \"/home/violeta/.local/lib/python3.8/site-packages/tensorflow/python/framework/func_graph.py\", line 990, in func_graph_from_py_func\n",
      "    func_outputs = python_func(*func_args, **func_kwargs)\n",
      "  File \"/home/violeta/.local/lib/python3.8/site-packages/tensorflow/python/eager/def_function.py\", line 634, in wrapped_fn\n",
      "    out = weak_wrapped_fn().__wrapped__(*args, **kwds)\n",
      "  File \"/home/violeta/.local/lib/python3.8/site-packages/tensorflow/python/framework/func_graph.py\", line 977, in wrapper\n",
      "    raise e.ag_error_metadata.to_exception(e)\n",
      "ValueError: in user code:\n",
      "\n",
      "    /home/violeta/.local/lib/python3.8/site-packages/tensorflow/python/keras/engine/training.py:805 train_function  *\n",
      "        return step_function(self, iterator)\n",
      "    /home/violeta/.local/lib/python3.8/site-packages/tensorflow/python/keras/engine/training.py:795 step_function  **\n",
      "        outputs = model.distribute_strategy.run(run_step, args=(data,))\n",
      "    /home/violeta/.local/lib/python3.8/site-packages/tensorflow/python/distribute/distribute_lib.py:1259 run\n",
      "        return self._extended.call_for_each_replica(fn, args=args, kwargs=kwargs)\n",
      "    /home/violeta/.local/lib/python3.8/site-packages/tensorflow/python/distribute/distribute_lib.py:2730 call_for_each_replica\n",
      "        return self._call_for_each_replica(fn, args, kwargs)\n",
      "    /home/violeta/.local/lib/python3.8/site-packages/tensorflow/python/distribute/distribute_lib.py:3417 _call_for_each_replica\n",
      "        return fn(*args, **kwargs)\n",
      "    /home/violeta/.local/lib/python3.8/site-packages/tensorflow/python/keras/engine/training.py:788 run_step  **\n",
      "        outputs = model.train_step(data)\n",
      "    /home/violeta/.local/lib/python3.8/site-packages/tensorflow/python/keras/engine/training.py:754 train_step\n",
      "        y_pred = self(x, training=True)\n",
      "    /home/violeta/.local/lib/python3.8/site-packages/tensorflow/python/keras/engine/base_layer.py:998 __call__\n",
      "        input_spec.assert_input_compatibility(self.input_spec, inputs, self.name)\n",
      "    /home/violeta/.local/lib/python3.8/site-packages/tensorflow/python/keras/engine/input_spec.py:255 assert_input_compatibility\n",
      "        raise ValueError(\n",
      "\n",
      "    ValueError: Input 0 of layer sequential_28 is incompatible with the layer: expected axis -1 of input shape to have value 55 but received input with shape (5, 4281)\n",
      "\n",
      "\n",
      "  warnings.warn(\"Estimator fit failed. The score on this train-test\"\n",
      "/home/violeta/.local/lib/python3.8/site-packages/sklearn/model_selection/_validation.py:610: FitFailedWarning: Estimator fit failed. The score on this train-test partition for these parameters will be set to nan. Details: \n",
      "Traceback (most recent call last):\n",
      "  File \"/home/violeta/.local/lib/python3.8/site-packages/sklearn/model_selection/_validation.py\", line 593, in _fit_and_score\n",
      "    estimator.fit(X_train, y_train, **fit_params)\n",
      "  File \"/home/violeta/.local/lib/python3.8/site-packages/tensorflow/python/keras/wrappers/scikit_learn.py\", line 223, in fit\n",
      "    return super(KerasClassifier, self).fit(x, y, **kwargs)\n",
      "  File \"/home/violeta/.local/lib/python3.8/site-packages/tensorflow/python/keras/wrappers/scikit_learn.py\", line 166, in fit\n",
      "    history = self.model.fit(x, y, **fit_args)\n",
      "  File \"/home/violeta/.local/lib/python3.8/site-packages/tensorflow/python/keras/engine/training.py\", line 1100, in fit\n",
      "    tmp_logs = self.train_function(iterator)\n",
      "  File \"/home/violeta/.local/lib/python3.8/site-packages/tensorflow/python/eager/def_function.py\", line 828, in __call__\n",
      "    result = self._call(*args, **kwds)\n",
      "  File \"/home/violeta/.local/lib/python3.8/site-packages/tensorflow/python/eager/def_function.py\", line 871, in _call\n",
      "    self._initialize(args, kwds, add_initializers_to=initializers)\n",
      "  File \"/home/violeta/.local/lib/python3.8/site-packages/tensorflow/python/eager/def_function.py\", line 725, in _initialize\n",
      "    self._stateful_fn._get_concrete_function_internal_garbage_collected(  # pylint: disable=protected-access\n",
      "  File \"/home/violeta/.local/lib/python3.8/site-packages/tensorflow/python/eager/function.py\", line 2969, in _get_concrete_function_internal_garbage_collected\n",
      "    graph_function, _ = self._maybe_define_function(args, kwargs)\n",
      "  File \"/home/violeta/.local/lib/python3.8/site-packages/tensorflow/python/eager/function.py\", line 3361, in _maybe_define_function\n",
      "    graph_function = self._create_graph_function(args, kwargs)\n",
      "  File \"/home/violeta/.local/lib/python3.8/site-packages/tensorflow/python/eager/function.py\", line 3196, in _create_graph_function\n",
      "    func_graph_module.func_graph_from_py_func(\n",
      "  File \"/home/violeta/.local/lib/python3.8/site-packages/tensorflow/python/framework/func_graph.py\", line 990, in func_graph_from_py_func\n",
      "    func_outputs = python_func(*func_args, **func_kwargs)\n",
      "  File \"/home/violeta/.local/lib/python3.8/site-packages/tensorflow/python/eager/def_function.py\", line 634, in wrapped_fn\n",
      "    out = weak_wrapped_fn().__wrapped__(*args, **kwds)\n",
      "  File \"/home/violeta/.local/lib/python3.8/site-packages/tensorflow/python/framework/func_graph.py\", line 977, in wrapper\n",
      "    raise e.ag_error_metadata.to_exception(e)\n",
      "ValueError: in user code:\n",
      "\n",
      "    /home/violeta/.local/lib/python3.8/site-packages/tensorflow/python/keras/engine/training.py:805 train_function  *\n",
      "        return step_function(self, iterator)\n",
      "    /home/violeta/.local/lib/python3.8/site-packages/tensorflow/python/keras/engine/training.py:795 step_function  **\n",
      "        outputs = model.distribute_strategy.run(run_step, args=(data,))\n",
      "    /home/violeta/.local/lib/python3.8/site-packages/tensorflow/python/distribute/distribute_lib.py:1259 run\n",
      "        return self._extended.call_for_each_replica(fn, args=args, kwargs=kwargs)\n",
      "    /home/violeta/.local/lib/python3.8/site-packages/tensorflow/python/distribute/distribute_lib.py:2730 call_for_each_replica\n",
      "        return self._call_for_each_replica(fn, args, kwargs)\n",
      "    /home/violeta/.local/lib/python3.8/site-packages/tensorflow/python/distribute/distribute_lib.py:3417 _call_for_each_replica\n",
      "        return fn(*args, **kwargs)\n",
      "    /home/violeta/.local/lib/python3.8/site-packages/tensorflow/python/keras/engine/training.py:788 run_step  **\n",
      "        outputs = model.train_step(data)\n",
      "    /home/violeta/.local/lib/python3.8/site-packages/tensorflow/python/keras/engine/training.py:754 train_step\n",
      "        y_pred = self(x, training=True)\n",
      "    /home/violeta/.local/lib/python3.8/site-packages/tensorflow/python/keras/engine/base_layer.py:998 __call__\n",
      "        input_spec.assert_input_compatibility(self.input_spec, inputs, self.name)\n",
      "    /home/violeta/.local/lib/python3.8/site-packages/tensorflow/python/keras/engine/input_spec.py:255 assert_input_compatibility\n",
      "        raise ValueError(\n",
      "\n",
      "    ValueError: Input 0 of layer sequential_29 is incompatible with the layer: expected axis -1 of input shape to have value 55 but received input with shape (5, 4281)\n",
      "\n",
      "\n",
      "  warnings.warn(\"Estimator fit failed. The score on this train-test\"\n"
     ]
    },
    {
     "name": "stderr",
     "output_type": "stream",
     "text": [
      "/home/violeta/.local/lib/python3.8/site-packages/sklearn/model_selection/_validation.py:610: FitFailedWarning: Estimator fit failed. The score on this train-test partition for these parameters will be set to nan. Details: \n",
      "Traceback (most recent call last):\n",
      "  File \"/home/violeta/.local/lib/python3.8/site-packages/sklearn/model_selection/_validation.py\", line 593, in _fit_and_score\n",
      "    estimator.fit(X_train, y_train, **fit_params)\n",
      "  File \"/home/violeta/.local/lib/python3.8/site-packages/tensorflow/python/keras/wrappers/scikit_learn.py\", line 223, in fit\n",
      "    return super(KerasClassifier, self).fit(x, y, **kwargs)\n",
      "  File \"/home/violeta/.local/lib/python3.8/site-packages/tensorflow/python/keras/wrappers/scikit_learn.py\", line 166, in fit\n",
      "    history = self.model.fit(x, y, **fit_args)\n",
      "  File \"/home/violeta/.local/lib/python3.8/site-packages/tensorflow/python/keras/engine/training.py\", line 1100, in fit\n",
      "    tmp_logs = self.train_function(iterator)\n",
      "  File \"/home/violeta/.local/lib/python3.8/site-packages/tensorflow/python/eager/def_function.py\", line 828, in __call__\n",
      "    result = self._call(*args, **kwds)\n",
      "  File \"/home/violeta/.local/lib/python3.8/site-packages/tensorflow/python/eager/def_function.py\", line 871, in _call\n",
      "    self._initialize(args, kwds, add_initializers_to=initializers)\n",
      "  File \"/home/violeta/.local/lib/python3.8/site-packages/tensorflow/python/eager/def_function.py\", line 725, in _initialize\n",
      "    self._stateful_fn._get_concrete_function_internal_garbage_collected(  # pylint: disable=protected-access\n",
      "  File \"/home/violeta/.local/lib/python3.8/site-packages/tensorflow/python/eager/function.py\", line 2969, in _get_concrete_function_internal_garbage_collected\n",
      "    graph_function, _ = self._maybe_define_function(args, kwargs)\n",
      "  File \"/home/violeta/.local/lib/python3.8/site-packages/tensorflow/python/eager/function.py\", line 3361, in _maybe_define_function\n",
      "    graph_function = self._create_graph_function(args, kwargs)\n",
      "  File \"/home/violeta/.local/lib/python3.8/site-packages/tensorflow/python/eager/function.py\", line 3196, in _create_graph_function\n",
      "    func_graph_module.func_graph_from_py_func(\n",
      "  File \"/home/violeta/.local/lib/python3.8/site-packages/tensorflow/python/framework/func_graph.py\", line 990, in func_graph_from_py_func\n",
      "    func_outputs = python_func(*func_args, **func_kwargs)\n",
      "  File \"/home/violeta/.local/lib/python3.8/site-packages/tensorflow/python/eager/def_function.py\", line 634, in wrapped_fn\n",
      "    out = weak_wrapped_fn().__wrapped__(*args, **kwds)\n",
      "  File \"/home/violeta/.local/lib/python3.8/site-packages/tensorflow/python/framework/func_graph.py\", line 977, in wrapper\n",
      "    raise e.ag_error_metadata.to_exception(e)\n",
      "ValueError: in user code:\n",
      "\n",
      "    /home/violeta/.local/lib/python3.8/site-packages/tensorflow/python/keras/engine/training.py:805 train_function  *\n",
      "        return step_function(self, iterator)\n",
      "    /home/violeta/.local/lib/python3.8/site-packages/tensorflow/python/keras/engine/training.py:795 step_function  **\n",
      "        outputs = model.distribute_strategy.run(run_step, args=(data,))\n",
      "    /home/violeta/.local/lib/python3.8/site-packages/tensorflow/python/distribute/distribute_lib.py:1259 run\n",
      "        return self._extended.call_for_each_replica(fn, args=args, kwargs=kwargs)\n",
      "    /home/violeta/.local/lib/python3.8/site-packages/tensorflow/python/distribute/distribute_lib.py:2730 call_for_each_replica\n",
      "        return self._call_for_each_replica(fn, args, kwargs)\n",
      "    /home/violeta/.local/lib/python3.8/site-packages/tensorflow/python/distribute/distribute_lib.py:3417 _call_for_each_replica\n",
      "        return fn(*args, **kwargs)\n",
      "    /home/violeta/.local/lib/python3.8/site-packages/tensorflow/python/keras/engine/training.py:788 run_step  **\n",
      "        outputs = model.train_step(data)\n",
      "    /home/violeta/.local/lib/python3.8/site-packages/tensorflow/python/keras/engine/training.py:754 train_step\n",
      "        y_pred = self(x, training=True)\n",
      "    /home/violeta/.local/lib/python3.8/site-packages/tensorflow/python/keras/engine/base_layer.py:998 __call__\n",
      "        input_spec.assert_input_compatibility(self.input_spec, inputs, self.name)\n",
      "    /home/violeta/.local/lib/python3.8/site-packages/tensorflow/python/keras/engine/input_spec.py:255 assert_input_compatibility\n",
      "        raise ValueError(\n",
      "\n",
      "    ValueError: Input 0 of layer sequential_30 is incompatible with the layer: expected axis -1 of input shape to have value 55 but received input with shape (None, 4281)\n",
      "\n",
      "\n",
      "  warnings.warn(\"Estimator fit failed. The score on this train-test\"\n",
      "/home/violeta/.local/lib/python3.8/site-packages/sklearn/model_selection/_validation.py:610: FitFailedWarning: Estimator fit failed. The score on this train-test partition for these parameters will be set to nan. Details: \n",
      "Traceback (most recent call last):\n",
      "  File \"/home/violeta/.local/lib/python3.8/site-packages/sklearn/model_selection/_validation.py\", line 593, in _fit_and_score\n",
      "    estimator.fit(X_train, y_train, **fit_params)\n",
      "  File \"/home/violeta/.local/lib/python3.8/site-packages/tensorflow/python/keras/wrappers/scikit_learn.py\", line 223, in fit\n",
      "    return super(KerasClassifier, self).fit(x, y, **kwargs)\n",
      "  File \"/home/violeta/.local/lib/python3.8/site-packages/tensorflow/python/keras/wrappers/scikit_learn.py\", line 166, in fit\n",
      "    history = self.model.fit(x, y, **fit_args)\n",
      "  File \"/home/violeta/.local/lib/python3.8/site-packages/tensorflow/python/keras/engine/training.py\", line 1100, in fit\n",
      "    tmp_logs = self.train_function(iterator)\n",
      "  File \"/home/violeta/.local/lib/python3.8/site-packages/tensorflow/python/eager/def_function.py\", line 828, in __call__\n",
      "    result = self._call(*args, **kwds)\n",
      "  File \"/home/violeta/.local/lib/python3.8/site-packages/tensorflow/python/eager/def_function.py\", line 871, in _call\n",
      "    self._initialize(args, kwds, add_initializers_to=initializers)\n",
      "  File \"/home/violeta/.local/lib/python3.8/site-packages/tensorflow/python/eager/def_function.py\", line 725, in _initialize\n",
      "    self._stateful_fn._get_concrete_function_internal_garbage_collected(  # pylint: disable=protected-access\n",
      "  File \"/home/violeta/.local/lib/python3.8/site-packages/tensorflow/python/eager/function.py\", line 2969, in _get_concrete_function_internal_garbage_collected\n",
      "    graph_function, _ = self._maybe_define_function(args, kwargs)\n",
      "  File \"/home/violeta/.local/lib/python3.8/site-packages/tensorflow/python/eager/function.py\", line 3361, in _maybe_define_function\n",
      "    graph_function = self._create_graph_function(args, kwargs)\n",
      "  File \"/home/violeta/.local/lib/python3.8/site-packages/tensorflow/python/eager/function.py\", line 3196, in _create_graph_function\n",
      "    func_graph_module.func_graph_from_py_func(\n",
      "  File \"/home/violeta/.local/lib/python3.8/site-packages/tensorflow/python/framework/func_graph.py\", line 990, in func_graph_from_py_func\n",
      "    func_outputs = python_func(*func_args, **func_kwargs)\n",
      "  File \"/home/violeta/.local/lib/python3.8/site-packages/tensorflow/python/eager/def_function.py\", line 634, in wrapped_fn\n",
      "    out = weak_wrapped_fn().__wrapped__(*args, **kwds)\n",
      "  File \"/home/violeta/.local/lib/python3.8/site-packages/tensorflow/python/framework/func_graph.py\", line 977, in wrapper\n",
      "    raise e.ag_error_metadata.to_exception(e)\n",
      "ValueError: in user code:\n",
      "\n",
      "    /home/violeta/.local/lib/python3.8/site-packages/tensorflow/python/keras/engine/training.py:805 train_function  *\n",
      "        return step_function(self, iterator)\n",
      "    /home/violeta/.local/lib/python3.8/site-packages/tensorflow/python/keras/engine/training.py:795 step_function  **\n",
      "        outputs = model.distribute_strategy.run(run_step, args=(data,))\n",
      "    /home/violeta/.local/lib/python3.8/site-packages/tensorflow/python/distribute/distribute_lib.py:1259 run\n",
      "        return self._extended.call_for_each_replica(fn, args=args, kwargs=kwargs)\n",
      "    /home/violeta/.local/lib/python3.8/site-packages/tensorflow/python/distribute/distribute_lib.py:2730 call_for_each_replica\n",
      "        return self._call_for_each_replica(fn, args, kwargs)\n",
      "    /home/violeta/.local/lib/python3.8/site-packages/tensorflow/python/distribute/distribute_lib.py:3417 _call_for_each_replica\n",
      "        return fn(*args, **kwargs)\n",
      "    /home/violeta/.local/lib/python3.8/site-packages/tensorflow/python/keras/engine/training.py:788 run_step  **\n",
      "        outputs = model.train_step(data)\n",
      "    /home/violeta/.local/lib/python3.8/site-packages/tensorflow/python/keras/engine/training.py:754 train_step\n",
      "        y_pred = self(x, training=True)\n",
      "    /home/violeta/.local/lib/python3.8/site-packages/tensorflow/python/keras/engine/base_layer.py:998 __call__\n",
      "        input_spec.assert_input_compatibility(self.input_spec, inputs, self.name)\n",
      "    /home/violeta/.local/lib/python3.8/site-packages/tensorflow/python/keras/engine/input_spec.py:255 assert_input_compatibility\n",
      "        raise ValueError(\n",
      "\n",
      "    ValueError: Input 0 of layer sequential_31 is incompatible with the layer: expected axis -1 of input shape to have value 55 but received input with shape (None, 4281)\n",
      "\n",
      "\n",
      "  warnings.warn(\"Estimator fit failed. The score on this train-test\"\n"
     ]
    },
    {
     "name": "stderr",
     "output_type": "stream",
     "text": [
      "/home/violeta/.local/lib/python3.8/site-packages/sklearn/model_selection/_validation.py:610: FitFailedWarning: Estimator fit failed. The score on this train-test partition for these parameters will be set to nan. Details: \n",
      "Traceback (most recent call last):\n",
      "  File \"/home/violeta/.local/lib/python3.8/site-packages/sklearn/model_selection/_validation.py\", line 593, in _fit_and_score\n",
      "    estimator.fit(X_train, y_train, **fit_params)\n",
      "  File \"/home/violeta/.local/lib/python3.8/site-packages/tensorflow/python/keras/wrappers/scikit_learn.py\", line 223, in fit\n",
      "    return super(KerasClassifier, self).fit(x, y, **kwargs)\n",
      "  File \"/home/violeta/.local/lib/python3.8/site-packages/tensorflow/python/keras/wrappers/scikit_learn.py\", line 166, in fit\n",
      "    history = self.model.fit(x, y, **fit_args)\n",
      "  File \"/home/violeta/.local/lib/python3.8/site-packages/tensorflow/python/keras/engine/training.py\", line 1100, in fit\n",
      "    tmp_logs = self.train_function(iterator)\n",
      "  File \"/home/violeta/.local/lib/python3.8/site-packages/tensorflow/python/eager/def_function.py\", line 828, in __call__\n",
      "    result = self._call(*args, **kwds)\n",
      "  File \"/home/violeta/.local/lib/python3.8/site-packages/tensorflow/python/eager/def_function.py\", line 871, in _call\n",
      "    self._initialize(args, kwds, add_initializers_to=initializers)\n",
      "  File \"/home/violeta/.local/lib/python3.8/site-packages/tensorflow/python/eager/def_function.py\", line 725, in _initialize\n",
      "    self._stateful_fn._get_concrete_function_internal_garbage_collected(  # pylint: disable=protected-access\n",
      "  File \"/home/violeta/.local/lib/python3.8/site-packages/tensorflow/python/eager/function.py\", line 2969, in _get_concrete_function_internal_garbage_collected\n",
      "    graph_function, _ = self._maybe_define_function(args, kwargs)\n",
      "  File \"/home/violeta/.local/lib/python3.8/site-packages/tensorflow/python/eager/function.py\", line 3361, in _maybe_define_function\n",
      "    graph_function = self._create_graph_function(args, kwargs)\n",
      "  File \"/home/violeta/.local/lib/python3.8/site-packages/tensorflow/python/eager/function.py\", line 3196, in _create_graph_function\n",
      "    func_graph_module.func_graph_from_py_func(\n",
      "  File \"/home/violeta/.local/lib/python3.8/site-packages/tensorflow/python/framework/func_graph.py\", line 990, in func_graph_from_py_func\n",
      "    func_outputs = python_func(*func_args, **func_kwargs)\n",
      "  File \"/home/violeta/.local/lib/python3.8/site-packages/tensorflow/python/eager/def_function.py\", line 634, in wrapped_fn\n",
      "    out = weak_wrapped_fn().__wrapped__(*args, **kwds)\n",
      "  File \"/home/violeta/.local/lib/python3.8/site-packages/tensorflow/python/framework/func_graph.py\", line 977, in wrapper\n",
      "    raise e.ag_error_metadata.to_exception(e)\n",
      "ValueError: in user code:\n",
      "\n",
      "    /home/violeta/.local/lib/python3.8/site-packages/tensorflow/python/keras/engine/training.py:805 train_function  *\n",
      "        return step_function(self, iterator)\n",
      "    /home/violeta/.local/lib/python3.8/site-packages/tensorflow/python/keras/engine/training.py:795 step_function  **\n",
      "        outputs = model.distribute_strategy.run(run_step, args=(data,))\n",
      "    /home/violeta/.local/lib/python3.8/site-packages/tensorflow/python/distribute/distribute_lib.py:1259 run\n",
      "        return self._extended.call_for_each_replica(fn, args=args, kwargs=kwargs)\n",
      "    /home/violeta/.local/lib/python3.8/site-packages/tensorflow/python/distribute/distribute_lib.py:2730 call_for_each_replica\n",
      "        return self._call_for_each_replica(fn, args, kwargs)\n",
      "    /home/violeta/.local/lib/python3.8/site-packages/tensorflow/python/distribute/distribute_lib.py:3417 _call_for_each_replica\n",
      "        return fn(*args, **kwargs)\n",
      "    /home/violeta/.local/lib/python3.8/site-packages/tensorflow/python/keras/engine/training.py:788 run_step  **\n",
      "        outputs = model.train_step(data)\n",
      "    /home/violeta/.local/lib/python3.8/site-packages/tensorflow/python/keras/engine/training.py:754 train_step\n",
      "        y_pred = self(x, training=True)\n",
      "    /home/violeta/.local/lib/python3.8/site-packages/tensorflow/python/keras/engine/base_layer.py:998 __call__\n",
      "        input_spec.assert_input_compatibility(self.input_spec, inputs, self.name)\n",
      "    /home/violeta/.local/lib/python3.8/site-packages/tensorflow/python/keras/engine/input_spec.py:255 assert_input_compatibility\n",
      "        raise ValueError(\n",
      "\n",
      "    ValueError: Input 0 of layer sequential_32 is incompatible with the layer: expected axis -1 of input shape to have value 55 but received input with shape (None, 4281)\n",
      "\n",
      "\n",
      "  warnings.warn(\"Estimator fit failed. The score on this train-test\"\n",
      "/home/violeta/.local/lib/python3.8/site-packages/sklearn/model_selection/_validation.py:610: FitFailedWarning: Estimator fit failed. The score on this train-test partition for these parameters will be set to nan. Details: \n",
      "Traceback (most recent call last):\n",
      "  File \"/home/violeta/.local/lib/python3.8/site-packages/sklearn/model_selection/_validation.py\", line 593, in _fit_and_score\n",
      "    estimator.fit(X_train, y_train, **fit_params)\n",
      "  File \"/home/violeta/.local/lib/python3.8/site-packages/tensorflow/python/keras/wrappers/scikit_learn.py\", line 223, in fit\n",
      "    return super(KerasClassifier, self).fit(x, y, **kwargs)\n",
      "  File \"/home/violeta/.local/lib/python3.8/site-packages/tensorflow/python/keras/wrappers/scikit_learn.py\", line 166, in fit\n",
      "    history = self.model.fit(x, y, **fit_args)\n",
      "  File \"/home/violeta/.local/lib/python3.8/site-packages/tensorflow/python/keras/engine/training.py\", line 1100, in fit\n",
      "    tmp_logs = self.train_function(iterator)\n",
      "  File \"/home/violeta/.local/lib/python3.8/site-packages/tensorflow/python/eager/def_function.py\", line 828, in __call__\n",
      "    result = self._call(*args, **kwds)\n",
      "  File \"/home/violeta/.local/lib/python3.8/site-packages/tensorflow/python/eager/def_function.py\", line 871, in _call\n",
      "    self._initialize(args, kwds, add_initializers_to=initializers)\n",
      "  File \"/home/violeta/.local/lib/python3.8/site-packages/tensorflow/python/eager/def_function.py\", line 725, in _initialize\n",
      "    self._stateful_fn._get_concrete_function_internal_garbage_collected(  # pylint: disable=protected-access\n",
      "  File \"/home/violeta/.local/lib/python3.8/site-packages/tensorflow/python/eager/function.py\", line 2969, in _get_concrete_function_internal_garbage_collected\n",
      "    graph_function, _ = self._maybe_define_function(args, kwargs)\n",
      "  File \"/home/violeta/.local/lib/python3.8/site-packages/tensorflow/python/eager/function.py\", line 3361, in _maybe_define_function\n",
      "    graph_function = self._create_graph_function(args, kwargs)\n",
      "  File \"/home/violeta/.local/lib/python3.8/site-packages/tensorflow/python/eager/function.py\", line 3196, in _create_graph_function\n",
      "    func_graph_module.func_graph_from_py_func(\n",
      "  File \"/home/violeta/.local/lib/python3.8/site-packages/tensorflow/python/framework/func_graph.py\", line 990, in func_graph_from_py_func\n",
      "    func_outputs = python_func(*func_args, **func_kwargs)\n",
      "  File \"/home/violeta/.local/lib/python3.8/site-packages/tensorflow/python/eager/def_function.py\", line 634, in wrapped_fn\n",
      "    out = weak_wrapped_fn().__wrapped__(*args, **kwds)\n",
      "  File \"/home/violeta/.local/lib/python3.8/site-packages/tensorflow/python/framework/func_graph.py\", line 977, in wrapper\n",
      "    raise e.ag_error_metadata.to_exception(e)\n",
      "ValueError: in user code:\n",
      "\n",
      "    /home/violeta/.local/lib/python3.8/site-packages/tensorflow/python/keras/engine/training.py:805 train_function  *\n",
      "        return step_function(self, iterator)\n",
      "    /home/violeta/.local/lib/python3.8/site-packages/tensorflow/python/keras/engine/training.py:795 step_function  **\n",
      "        outputs = model.distribute_strategy.run(run_step, args=(data,))\n",
      "    /home/violeta/.local/lib/python3.8/site-packages/tensorflow/python/distribute/distribute_lib.py:1259 run\n",
      "        return self._extended.call_for_each_replica(fn, args=args, kwargs=kwargs)\n",
      "    /home/violeta/.local/lib/python3.8/site-packages/tensorflow/python/distribute/distribute_lib.py:2730 call_for_each_replica\n",
      "        return self._call_for_each_replica(fn, args, kwargs)\n",
      "    /home/violeta/.local/lib/python3.8/site-packages/tensorflow/python/distribute/distribute_lib.py:3417 _call_for_each_replica\n",
      "        return fn(*args, **kwargs)\n",
      "    /home/violeta/.local/lib/python3.8/site-packages/tensorflow/python/keras/engine/training.py:788 run_step  **\n",
      "        outputs = model.train_step(data)\n",
      "    /home/violeta/.local/lib/python3.8/site-packages/tensorflow/python/keras/engine/training.py:754 train_step\n",
      "        y_pred = self(x, training=True)\n",
      "    /home/violeta/.local/lib/python3.8/site-packages/tensorflow/python/keras/engine/base_layer.py:998 __call__\n",
      "        input_spec.assert_input_compatibility(self.input_spec, inputs, self.name)\n",
      "    /home/violeta/.local/lib/python3.8/site-packages/tensorflow/python/keras/engine/input_spec.py:255 assert_input_compatibility\n",
      "        raise ValueError(\n",
      "\n",
      "    ValueError: Input 0 of layer sequential_33 is incompatible with the layer: expected axis -1 of input shape to have value 55 but received input with shape (5, 4281)\n",
      "\n",
      "\n",
      "  warnings.warn(\"Estimator fit failed. The score on this train-test\"\n"
     ]
    }
   ],
   "source": [
    "DNN = dnn(x_train, y_train, x_validation, y_validation)"
   ]
  },
  {
   "cell_type": "code",
   "execution_count": null,
   "metadata": {},
   "outputs": [],
   "source": [
    "test_model(DNN, x_validation, y_validation)\n",
    "cross_val(DNN, x_train, y_train)"
   ]
  },
  {
   "cell_type": "markdown",
   "metadata": {},
   "source": [
    "## PERCEPTRON"
   ]
  },
  {
   "cell_type": "code",
   "execution_count": null,
   "metadata": {},
   "outputs": [],
   "source": [
    "PERC = multi_perceptron(x_train, y_train, x_validation, y_validation)\n",
    "test_model(PERC, x_validation, y_validation)\n",
    "cross_val(PERC, x_train, y_train)"
   ]
  }
 ],
 "metadata": {
  "kernelspec": {
   "display_name": "Python 3",
   "language": "python",
   "name": "python3"
  },
  "language_info": {
   "codemirror_mode": {
    "name": "ipython",
    "version": 3
   },
   "file_extension": ".py",
   "mimetype": "text/x-python",
   "name": "python",
   "nbconvert_exporter": "python",
   "pygments_lexer": "ipython3",
   "version": "3.8.5"
  }
 },
 "nbformat": 4,
 "nbformat_minor": 4
}
